Workbook

Sheet Resumo 2023
A1: Categoria | B1: Janeiro | C1: Fevereiro | D1: março | E1: abril | F1: maio | G1: jun | H1: jul | I1: Agosto | J1: setembro | K1: outubro | L1: novembro | M1: dezembro | N1: 45315 | O1: 45340 | P1: 45369 | Q1: 45400 | R1: 45430 | S1: 45461 | T1: 45545 | U1: 45682 | V1: 45713 | W1: 45741 | X1: 45772 | Y1: 45802 | Z1: 45833 | AA1: 45863 | AB1: 45894 | AC1: media 5meses
A2: escola/faculdade | B2: =Janeiro23!B67 -> 883 | C2: =fevereiro23!B102 -> 2797.99 | D2: =ifna(VLOOKUP(A2, marco23!$A$97:$B$119, 2, FALSE),0) -> 1593 | E2: =ifna(VLOOKUP(A2, abril23!$A$82:$B$103, 2, FALSE),0) -> 888 | F2: =ifna(VLOOKUP(A2, maio23!$A$95:$B$117, 2, FALSE),0) -> 1458.0273 | G2: =ifna(VLOOKUP(A2, junho23!$A$127:$B$152, 2, FALSE),0) -> 1458.0273 | H2: =ifna(VLOOKUP(A2, julho23!$A$139:$B$164, 2, FALSE),0) -> 1458.0273 | I2: =ifna(VLOOKUP(A2, Agosto23!$A$127:$B$152, 2, FALSE),0) -> 1724.0364 | J2: =ifna(VLOOKUP(A2, setembro23!$A$125:$B$151, 2, FALSE),0) -> 1268 | K2: =ifna(VLOOKUP(A2, outubro23!$A$121:$B$146, 2, FALSE),0) -> 1652 | L2: =ifna(VLOOKUP(A2, novembro23!$A$121:$B$146, 2, FALSE),0) -> 1652 | M2: =ifna(VLOOKUP(A2, Dezembro23!$A$127:$B$152, 2, FALSE),0) -> 2523.5 | N2: =ifna(VLOOKUP(A2, janneiro24!$A$127:$B$152, 2, FALSE),0) -> 799.49 | O2: =ifna(VLOOKUP(A2, fevereiro24!$A$127:$B$152, 2, FALSE),0) -> 2459.3928 | P2: =ifna(VLOOKUP(A2, marco24!$A$127:$B$152, 2, FALSE),0) -> 1808.31 | Q2: =ifna(VLOOKUP(A2, abril24!$A$127:$B$152, 2, FALSE),0) -> 1808.31 | R2: =ifna(VLOOKUP(A2, maio24!$A$127:$B$152, 2, FALSE),0) -> 1808.31 | S2: =ifna(VLOOKUP(A2, 'jun24'!$A$127:$B$152, 2, FALSE),0) -> 1819.3 | T2: =ifna(VLOOKUP(A2, 'set24'!$A$127:$B$152, 2, FALSE),0) -> 1490.22 | U2: =ifna(VLOOKUP(A2, 'jan25'!$A$127:$B$152, 2, FALSE),0) -> 1729.94 | V2: =ifna(VLOOKUP(A2, 'fev25'!$A$132:$B$157, 2, FALSE),0) -> 1345.63 | W2: =ifna(VLOOKUP(A2, 'mar25'!$A$125:$B$153, 2, FALSE),0) -> 1484.78 | X2: =ifna(VLOOKUP(A2, 'abr25'!$A$131:$B$157, 2, FALSE),0) -> 1474 | Y2: =ifna(VLOOKUP(A2, 'mai25'!$A$142:$B$174, 2, FALSE),0) -> 1474 | Z2: =ifna(VLOOKUP(A2, 'jun25'!$A$141:$B$169, 2, FALSE),0) -> 1474.78 | AA2: =ifna(VLOOKUP(A2, 'jul25'!$A$141:$B$170, 2, FALSE),0) -> 1639 | AB2: =ifna(VLOOKUP(A2, 'ago25'!$A$141:$B$170, 2, FALSE),0) -> 1639 | AC2: =AVERAGE(X2:AA2) -> 1515.445
A3: gift | B3: =Janeiro23!B52 -> 0 | C3: =fevereiro23!B97 -> 492.99 | D3: =ifna(VLOOKUP(A3, marco23!$A$97:$B$119, 2, FALSE),0) -> 492.99 | E3: =ifna(VLOOKUP(A3, abril23!$A$82:$B$103, 2, FALSE),0) -> 1911.33 | F3: =ifna(VLOOKUP(A3, maio23!$A$95:$B$117, 2, FALSE),0) -> 258.22 | G3: =ifna(VLOOKUP(A3, junho23!$A$127:$B$152, 2, FALSE),0) -> 238.8 | H3: =ifna(VLOOKUP(A3, julho23!$A$139:$B$164, 2, FALSE),0) -> 109.99 | I3: =ifna(VLOOKUP(A3, Agosto23!$A$127:$B$152, 2, FALSE),0) -> 0 | J3: =ifna(VLOOKUP(A3, setembro23!$A$125:$B$151, 2, FALSE),0) -> 362.95 | K3: =ifna(VLOOKUP(A3, outubro23!$A$121:$B$146, 2, FALSE),0) -> 224.99 | L3: =ifna(VLOOKUP(A3, novembro23!$A$121:$B$146, 2, FALSE),0) -> 0 | M3: =ifna(VLOOKUP(A3, Dezembro23!$A$127:$B$152, 2, FALSE),0) -> 188.9 | N3: =ifna(VLOOKUP(A3, janneiro24!$A$127:$B$152, 2, FALSE),0) -> 0 | O3: =ifna(VLOOKUP(A3, fevereiro24!$A$127:$B$152, 2, FALSE),0) -> 0 | P3: =ifna(VLOOKUP(A3, marco24!$A$127:$B$152, 2, FALSE),0) -> 69 | Q3: =ifna(VLOOKUP(A3, abril24!$A$127:$B$152, 2, FALSE),0) -> 323.56 | R3: =ifna(VLOOKUP(A3, maio24!$A$127:$B$152, 2, FALSE),0) -> 49.9 | S3: =ifna(VLOOKUP(A3, 'jun24'!$A$127:$B$152, 2, FALSE),0) -> 249.84 | T3: =ifna(VLOOKUP(A3, 'set24'!$A$127:$B$152, 2, FALSE),0) -> 124.79 | U3: =ifna(VLOOKUP(A3, 'jan25'!$A$127:$B$152, 2, FALSE),0) -> 0 | V3: =ifna(VLOOKUP(A3, 'fev25'!$A$132:$B$157, 2, FALSE),0) -> 533.59 | W3: =ifna(VLOOKUP(A3, 'mar25'!$A$125:$B$153, 2, FALSE),0) -> 252.09 | X3: =ifna(VLOOKUP(A3, 'abr25'!$A$131:$B$157, 2, FALSE),0) -> 937.38 | Y3: =ifna(VLOOKUP(A3, 'mai25'!$A$142:$B$174, 2, FALSE),0) -> 634.06 | Z3: =ifna(VLOOKUP(A3, 'jun25'!$A$141:$B$169, 2, FALSE),0) -> 590.17 | AA3: =ifna(VLOOKUP(A3, 'jul25'!$A$141:$B$170, 2, FALSE),0) -> 1049.91 | AB3: =ifna(VLOOKUP(A3, 'ago25'!$A$141:$B$170, 2, FALSE),0) -> 389.98 | AC3: =AVERAGE(X3:AA3) -> 802.88
A4: cursos | B4: =Janeiro23!B53 -> 37.9 | C4: =fevereiro23!B83 -> 37.9 | D4: =ifna(VLOOKUP(A4, marco23!$A$97:$B$119, 2, FALSE),0) -> 37.9 | E4: =ifna(VLOOKUP(A4, abril23!$A$82:$B$103, 2, FALSE),0) -> 37.9 | F4: =ifna(VLOOKUP(A4, maio23!$A$95:$B$117, 2, FALSE),0) -> 37.9 | G4: =ifna(VLOOKUP(A4, junho23!$A$127:$B$152, 2, FALSE),0) -> 0 | H4: =ifna(VLOOKUP(A4, julho23!$A$139:$B$164, 2, FALSE),0) -> 0 | I4: =ifna(VLOOKUP(A4, Agosto23!$A$127:$B$152, 2, FALSE),0) -> 0 | J4: =ifna(VLOOKUP(A4, setembro23!$A$125:$B$151, 2, FALSE),0) -> 0 | K4: =ifna(VLOOKUP(A4, outubro23!$A$121:$B$146, 2, FALSE),0) -> 1326.51 | L4: =ifna(VLOOKUP(A4, novembro23!$A$121:$B$146, 2, FALSE),0) -> 0 | M4: =ifna(VLOOKUP(A4, Dezembro23!$A$127:$B$152, 2, FALSE),0) -> 0 | N4: =ifna(VLOOKUP(A4, janneiro24!$A$127:$B$152, 2, FALSE),0) -> 0 | O4: =ifna(VLOOKUP(A4, fevereiro24!$A$127:$B$152, 2, FALSE),0) -> 0 | P4: =ifna(VLOOKUP(A4, marco24!$A$127:$B$152, 2, FALSE),0) -> 0 | Q4: =ifna(VLOOKUP(A4, abril24!$A$127:$B$152, 2, FALSE),0) -> 0 | R4: =ifna(VLOOKUP(A4, maio24!$A$127:$B$152, 2, FALSE),0) -> 0 | S4: =ifna(VLOOKUP(A4, 'jun24'!$A$127:$B$152, 2, FALSE),0) -> 0 | T4: =ifna(VLOOKUP(A4, 'set24'!$A$127:$B$152, 2, FALSE),0) -> 0 | U4: =ifna(VLOOKUP(A4, 'jan25'!$A$127:$B$152, 2, FALSE),0) -> 0 | V4: =ifna(VLOOKUP(A4, 'fev25'!$A$132:$B$157, 2, FALSE),0) -> 0 | W4: =ifna(VLOOKUP(A4, 'mar25'!$A$125:$B$153, 2, FALSE),0) -> 0 | X4: =ifna(VLOOKUP(A4, 'abr25'!$A$131:$B$157, 2, FALSE),0) -> 0 | Y4: =ifna(VLOOKUP(A4, 'mai25'!$A$142:$B$174, 2, FALSE),0) -> 2457.12 | Z4: =ifna(VLOOKUP(A4, 'jun25'!$A$141:$B$169, 2, FALSE),0) -> 380.12 | AA4: =ifna(VLOOKUP(A4, 'jul25'!$A$141:$B$170, 2, FALSE),0) -> 380 | AB4: =ifna(VLOOKUP(A4, 'ago25'!$A$141:$B$170, 2, FALSE),0) -> 380 | AC4: =AVERAGE(X4:AA4) -> 804.31
A5: streaming | B5: =Janeiro23!B54 -> 78.65 | C5: =fevereiro23!B85 -> 78.65 | D5: =ifna(VLOOKUP(A5, marco23!$A$97:$B$119, 2, FALSE),0) -> 78.65 | E5: =ifna(VLOOKUP(A5, abril23!$A$82:$B$103, 2, FALSE),0) -> 93.55 | F5: =ifna(VLOOKUP(A5, maio23!$A$95:$B$117, 2, FALSE),0) -> 93.55 | G5: =ifna(VLOOKUP(A5, junho23!$A$127:$B$152, 2, FALSE),0) -> 93.55 | H5: =ifna(VLOOKUP(A5, julho23!$A$139:$B$164, 2, FALSE),0) -> 102.14 | I5: =ifna(VLOOKUP(A5, Agosto23!$A$127:$B$152, 2, FALSE),0) -> 102.14 | J5: =ifna(VLOOKUP(A5, setembro23!$A$125:$B$151, 2, FALSE),0) -> 102.14 | K5: =ifna(VLOOKUP(A5, outubro23!$A$121:$B$146, 2, FALSE),0) -> 102.14 | L5: =ifna(VLOOKUP(A5, novembro23!$A$121:$B$146, 2, FALSE),0) -> 102.14 | M5: =ifna(VLOOKUP(A5, Dezembro23!$A$127:$B$152, 2, FALSE),0) -> 112.14 | N5: =ifna(VLOOKUP(A5, janneiro24!$A$127:$B$152, 2, FALSE),0) -> 90.24 | O5: =ifna(VLOOKUP(A5, fevereiro24!$A$127:$B$152, 2, FALSE),0) -> 90.24 | P5: =ifna(VLOOKUP(A5, marco24!$A$127:$B$152, 2, FALSE),0) -> 90.24 | Q5: =ifna(VLOOKUP(A5, abril24!$A$127:$B$152, 2, FALSE),0) -> 90.24 | R5: =ifna(VLOOKUP(A5, maio24!$A$127:$B$152, 2, FALSE),0) -> 90.24 | S5: =ifna(VLOOKUP(A5, 'jun24'!$A$127:$B$152, 2, FALSE),0) -> 242 | T5: =ifna(VLOOKUP(A5, 'set24'!$A$127:$B$152, 2, FALSE),0) -> 82.84 | U5: =ifna(VLOOKUP(A5, 'jan25'!$A$127:$B$152, 2, FALSE),0) -> 92.84 | V5: =ifna(VLOOKUP(A5, 'fev25'!$A$132:$B$157, 2, FALSE),0) -> 92.84 | W5: =ifna(VLOOKUP(A5, 'mar25'!$A$125:$B$153, 2, FALSE),0) -> 92.84 | X5: =ifna(VLOOKUP(A5, 'abr25'!$A$131:$B$157, 2, FALSE),0) -> 89.75 | Y5: =ifna(VLOOKUP(A5, 'mai25'!$A$142:$B$174, 2, FALSE),0) -> 89.75 | Z5: =ifna(VLOOKUP(A5, 'jun25'!$A$141:$B$169, 2, FALSE),0) -> 255.75 | AA5: =ifna(VLOOKUP(A5, 'jul25'!$A$141:$B$170, 2, FALSE),0) -> 89.75 | AB5: =ifna(VLOOKUP(A5, 'ago25'!$A$141:$B$170, 2, FALSE),0) -> 89.75 | AC5: =AVERAGE(X5:AA5) -> 131.25
A6: combustivel | B6: =Janeiro23!B55 -> 85.71 | C6: =fevereiro23!B91 -> 199.85 | D6: =ifna(VLOOKUP(A6, marco23!$A$97:$B$119, 2, FALSE),0) -> 228.26 | E6: =ifna(VLOOKUP(A6, abril23!$A$82:$B$103, 2, FALSE),0) -> 250 | F6: =ifna(VLOOKUP(A6, maio23!$A$95:$B$117, 2, FALSE),0) -> 201.84 | G6: =ifna(VLOOKUP(A6, junho23!$A$127:$B$152, 2, FALSE),0) -> 431.69 | H6: =ifna(VLOOKUP(A6, julho23!$A$139:$B$164, 2, FALSE),0) -> 118.08 | I6: =ifna(VLOOKUP(A6, Agosto23!$A$127:$B$152, 2, FALSE),0) -> 289.23 | J6: =ifna(VLOOKUP(A6, setembro23!$A$125:$B$151, 2, FALSE),0) -> 251.2 | K6: =ifna(VLOOKUP(A6, outubro23!$A$121:$B$146, 2, FALSE),0) -> 253.05 | L6: =ifna(VLOOKUP(A6, novembro23!$A$121:$B$146, 2, FALSE),0) -> 321.44 | M6: =ifna(VLOOKUP(A6, Dezembro23!$A$127:$B$152, 2, FALSE),0) -> 275.64 | N6: =ifna(VLOOKUP(A6, janneiro24!$A$127:$B$152, 2, FALSE),0) -> 168.12 | O6: =ifna(VLOOKUP(A6, fevereiro24!$A$127:$B$152, 2, FALSE),0) -> 168.12 | P6: =ifna(VLOOKUP(A6, marco24!$A$127:$B$152, 2, FALSE),0) -> 493.4 | Q6: =ifna(VLOOKUP(A6, abril24!$A$127:$B$152, 2, FALSE),0) -> 433.48 | R6: =ifna(VLOOKUP(A6, maio24!$A$127:$B$152, 2, FALSE),0) -> 568.77 | S6: =ifna(VLOOKUP(A6, 'jun24'!$A$127:$B$152, 2, FALSE),0) -> 253.43 | T6: =ifna(VLOOKUP(A6, 'set24'!$A$127:$B$152, 2, FALSE),0) -> 216.68 | U6: =ifna(VLOOKUP(A6, 'jan25'!$A$127:$B$152, 2, FALSE),0) -> 0 | V6: =ifna(VLOOKUP(A6, 'fev25'!$A$132:$B$157, 2, FALSE),0) -> 340.84 | W6: =ifna(VLOOKUP(A6, 'mar25'!$A$125:$B$153, 2, FALSE),0) -> 280.69 | X6: =ifna(VLOOKUP(A6, 'abr25'!$A$131:$B$157, 2, FALSE),0) -> 358.38 | Y6: =ifna(VLOOKUP(A6, 'mai25'!$A$142:$B$174, 2, FALSE),0) -> 334.45 | Z6: =ifna(VLOOKUP(A6, 'jun25'!$A$141:$B$169, 2, FALSE),0) -> 365.93 | AA6: =ifna(VLOOKUP(A6, 'jul25'!$A$141:$B$170, 2, FALSE),0) -> 382.92 | AB6: =ifna(VLOOKUP(A6, 'ago25'!$A$141:$B$170, 2, FALSE),0) -> 301.94 | AC6: =AVERAGE(X6:AA6) -> 360.42
A7: contabilidade | B7: =Janeiro23!B56 -> 89.9 | C7: =fevereiro23!B86 -> 89.9 | D7: =ifna(VLOOKUP(A7, marco23!$A$97:$B$119, 2, FALSE),0) -> 89.9 | E7: =ifna(VLOOKUP(A7, abril23!$A$82:$B$103, 2, FALSE),0) -> 89.9 | F7: =ifna(VLOOKUP(A7, maio23!$A$95:$B$117, 2, FALSE),0) -> 89.9 | G7: =ifna(VLOOKUP(A7, junho23!$A$127:$B$152, 2, FALSE),0) -> 89.9 | H7: =ifna(VLOOKUP(A7, julho23!$A$139:$B$164, 2, FALSE),0) -> 89.9 | I7: =ifna(VLOOKUP(A7, Agosto23!$A$127:$B$152, 2, FALSE),0) -> 89.9 | J7: =ifna(VLOOKUP(A7, setembro23!$A$125:$B$151, 2, FALSE),0) -> 89.9 | K7: =ifna(VLOOKUP(A7, outubro23!$A$121:$B$146, 2, FALSE),0) -> 89.9 | L7: =ifna(VLOOKUP(A7, novembro23!$A$121:$B$146, 2, FALSE),0) -> 89.9 | M7: =ifna(VLOOKUP(A7, Dezembro23!$A$127:$B$152, 2, FALSE),0) -> 89.9 | N7: =ifna(VLOOKUP(A7, janneiro24!$A$127:$B$152, 2, FALSE),0) -> 100 | O7: =ifna(VLOOKUP(A7, fevereiro24!$A$127:$B$152, 2, FALSE),0) -> 89.9 | P7: =ifna(VLOOKUP(A7, marco24!$A$127:$B$152, 2, FALSE),0) -> 100.46 | Q7: =ifna(VLOOKUP(A7, abril24!$A$127:$B$152, 2, FALSE),0) -> 100.46 | R7: =ifna(VLOOKUP(A7, maio24!$A$127:$B$152, 2, FALSE),0) -> 100.46 | S7: =ifna(VLOOKUP(A7, 'jun24'!$A$127:$B$152, 2, FALSE),0) -> 100.46 | T7: =ifna(VLOOKUP(A7, 'set24'!$A$127:$B$152, 2, FALSE),0) -> 100.46 | U7: =ifna(VLOOKUP(A7, 'jan25'!$A$127:$B$152, 2, FALSE),0) -> 0 | V7: =ifna(VLOOKUP(A7, 'fev25'!$A$132:$B$157, 2, FALSE),0) -> 0 | W7: =ifna(VLOOKUP(A7, 'mar25'!$A$125:$B$153, 2, FALSE),0) -> 0 | X7: =ifna(VLOOKUP(A7, 'abr25'!$A$131:$B$157, 2, FALSE),0) -> 0 | Y7: =ifna(VLOOKUP(A7, 'mai25'!$A$142:$B$174, 2, FALSE),0) -> 0 | Z7: =ifna(VLOOKUP(A7, 'jun25'!$A$141:$B$169, 2, FALSE),0) -> 0 | AA7: =ifna(VLOOKUP(A7, 'jul25'!$A$141:$B$170, 2, FALSE),0) -> 0 | AB7: =ifna(VLOOKUP(A7, 'ago25'!$A$141:$B$170, 2, FALSE),0) -> 0 | AC7: =AVERAGE(X7:AA7) -> 0
A8: estacionamentos | B8: =Janeiro23!B57 -> 92 | C8: =0 -> 0 | D8: =ifna(VLOOKUP(A8, marco23!$A$97:$B$119, 2, FALSE),0) -> 0 | E8: =ifna(VLOOKUP(A8, abril23!$A$82:$B$103, 2, FALSE),0) -> 0 | F8: =ifna(VLOOKUP(A8, maio23!$A$95:$B$117, 2, FALSE),0) -> 0 | G8: =ifna(VLOOKUP(A8, junho23!$A$127:$B$152, 2, FALSE),0) -> 0 | H8: =ifna(VLOOKUP(A8, julho23!$A$139:$B$164, 2, FALSE),0) -> 0 | I8: =ifna(VLOOKUP(A8, Agosto23!$A$127:$B$152, 2, FALSE),0) -> 0 | J8: =ifna(VLOOKUP(A8, setembro23!$A$125:$B$151, 2, FALSE),0) -> 0 | K8: =ifna(VLOOKUP(A8, outubro23!$A$121:$B$146, 2, FALSE),0) -> 36 | L8: =ifna(VLOOKUP(A8, novembro23!$A$121:$B$146, 2, FALSE),0) -> 17 | M8: =ifna(VLOOKUP(A8, Dezembro23!$A$127:$B$152, 2, FALSE),0) -> 25 | N8: =ifna(VLOOKUP(A8, janneiro24!$A$127:$B$152, 2, FALSE),0) -> 0 | O8: =ifna(VLOOKUP(A8, fevereiro24!$A$127:$B$152, 2, FALSE),0) -> 0 | P8: =ifna(VLOOKUP(A8, marco24!$A$127:$B$152, 2, FALSE),0) -> 0 | Q8: =ifna(VLOOKUP(A8, abril24!$A$127:$B$152, 2, FALSE),0) -> 40 | R8: =ifna(VLOOKUP(A8, maio24!$A$127:$B$152, 2, FALSE),0) -> 8 | S8: =ifna(VLOOKUP(A8, 'jun24'!$A$127:$B$152, 2, FALSE),0) -> 0 | T8: =ifna(VLOOKUP(A8, 'set24'!$A$127:$B$152, 2, FALSE),0) -> 5 | U8: =ifna(VLOOKUP(A8, 'jan25'!$A$127:$B$152, 2, FALSE),0) -> 0 | V8: =ifna(VLOOKUP(A8, 'fev25'!$A$132:$B$157, 2, FALSE),0) -> 10 | W8: =ifna(VLOOKUP(A8, 'mar25'!$A$125:$B$153, 2, FALSE),0) -> 8 | X8: =ifna(VLOOKUP(A8, 'abr25'!$A$131:$B$157, 2, FALSE),0) -> 16 | Y8: =ifna(VLOOKUP(A8, 'mai25'!$A$142:$B$174, 2, FALSE),0) -> 46 | Z8: =ifna(VLOOKUP(A8, 'jun25'!$A$141:$B$169, 2, FALSE),0) -> 27.4 | AA8: =ifna(VLOOKUP(A8, 'jul25'!$A$141:$B$170, 2, FALSE),0) -> 16 | AB8: =ifna(VLOOKUP(A8, 'ago25'!$A$141:$B$170, 2, FALSE),0) -> 42 | AC8: =AVERAGE(X8:AA8) -> 26.35
A9: Internet movel | B9: =Janeiro23!B58 -> 99 | C9: =fevereiro23!B88 -> 99 | D9: =ifna(VLOOKUP(A9, marco23!$A$97:$B$119, 2, FALSE),0) -> 99 | E9: =ifna(VLOOKUP(A9, abril23!$A$82:$B$103, 2, FALSE),0) -> 88 | F9: =ifna(VLOOKUP(A9, maio23!$A$95:$B$117, 2, FALSE),0) -> 88 | G9: =ifna(VLOOKUP(A9, junho23!$A$127:$B$152, 2, FALSE),0) -> 148 | H9: =ifna(VLOOKUP(A9, julho23!$A$139:$B$164, 2, FALSE),0) -> 88 | I9: =ifna(VLOOKUP(A9, Agosto23!$A$127:$B$152, 2, FALSE),0) -> 88 | J9: =ifna(VLOOKUP(A9, setembro23!$A$125:$B$151, 2, FALSE),0) -> 88 | K9: =ifna(VLOOKUP(A9, outubro23!$A$121:$B$146, 2, FALSE),0) -> 88 | L9: =ifna(VLOOKUP(A9, novembro23!$A$121:$B$146, 2, FALSE),0) -> 88 | M9: =ifna(VLOOKUP(A9, Dezembro23!$A$127:$B$152, 2, FALSE),0) -> 138 | N9: =ifna(VLOOKUP(A9, janneiro24!$A$127:$B$152, 2, FALSE),0) -> 88 | O9: =ifna(VLOOKUP(A9, fevereiro24!$A$127:$B$152, 2, FALSE),0) -> 88 | P9: =ifna(VLOOKUP(A9, marco24!$A$127:$B$152, 2, FALSE),0) -> 88 | Q9: =ifna(VLOOKUP(A9, abril24!$A$127:$B$152, 2, FALSE),0) -> 88 | R9: =ifna(VLOOKUP(A9, maio24!$A$127:$B$152, 2, FALSE),0) -> 88 | S9: =ifna(VLOOKUP(A9, 'jun24'!$A$127:$B$152, 2, FALSE),0) -> 88 | T9: =ifna(VLOOKUP(A9, 'set24'!$A$127:$B$152, 2, FALSE),0) -> 162.3 | U9: =ifna(VLOOKUP(A9, 'jan25'!$A$127:$B$152, 2, FALSE),0) -> 88 | V9: =ifna(VLOOKUP(A9, 'fev25'!$A$132:$B$157, 2, FALSE),0) -> 181.1 | W9: =ifna(VLOOKUP(A9, 'mar25'!$A$125:$B$153, 2, FALSE),0) -> 149.9 | X9: =ifna(VLOOKUP(A9, 'abr25'!$A$131:$B$157, 2, FALSE),0) -> 149.9 | Y9: =ifna(VLOOKUP(A9, 'mai25'!$A$142:$B$174, 2, FALSE),0) -> 138 | Z9: =ifna(VLOOKUP(A9, 'jun25'!$A$141:$B$169, 2, FALSE),0) -> 149.9 | AA9: =ifna(VLOOKUP(A9, 'jul25'!$A$141:$B$170, 2, FALSE),0) -> 99.9 | AB9: =ifna(VLOOKUP(A9, 'ago25'!$A$141:$B$170, 2, FALSE),0) -> 99.9 | AC9: =AVERAGE(X9:AA9) -> 134.425
A10: Internet | B10: =Janeiro23!B59 -> 104 | C10: =fevereiro23!B89 -> 104 | D10: =ifna(VLOOKUP(A10, marco23!$A$97:$B$119, 2, FALSE),0) -> 104 | E10: =ifna(VLOOKUP(A10, abril23!$A$82:$B$103, 2, FALSE),0) -> 119.83 | F10: =ifna(VLOOKUP(A10, maio23!$A$95:$B$117, 2, FALSE),0) -> 99 | G10: =ifna(VLOOKUP(A10, junho23!$A$127:$B$152, 2, FALSE),0) -> 99 | H10: =ifna(VLOOKUP(A10, julho23!$A$139:$B$164, 2, FALSE),0) -> 99 | I10: =ifna(VLOOKUP(A10, Agosto23!$A$127:$B$152, 2, FALSE),0) -> 99 | J10: =ifna(VLOOKUP(A10, setembro23!$A$125:$B$151, 2, FALSE),0) -> 99 | K10: =ifna(VLOOKUP(A10, outubro23!$A$121:$B$146, 2, FALSE),0) -> 99 | L10: =ifna(VLOOKUP(A10, novembro23!$A$121:$B$146, 2, FALSE),0) -> 99 | M10: =ifna(VLOOKUP(A10, Dezembro23!$A$127:$B$152, 2, FALSE),0) -> 99 | N10: =ifna(VLOOKUP(A10, janneiro24!$A$127:$B$152, 2, FALSE),0) -> 129 | O10: =ifna(VLOOKUP(A10, fevereiro24!$A$127:$B$152, 2, FALSE),0) -> 129 | P10: =ifna(VLOOKUP(A10, marco24!$A$127:$B$152, 2, FALSE),0) -> 129 | Q10: =ifna(VLOOKUP(A10, abril24!$A$127:$B$152, 2, FALSE),0) -> 129 | R10: =ifna(VLOOKUP(A10, maio24!$A$127:$B$152, 2, FALSE),0) -> 129 | S10: =ifna(VLOOKUP(A10, 'jun24'!$A$127:$B$152, 2, FALSE),0) -> 129 | T10: =ifna(VLOOKUP(A10, 'set24'!$A$127:$B$152, 2, FALSE),0) -> 1825.42 | U10: =ifna(VLOOKUP(A10, 'jan25'!$A$127:$B$152, 2, FALSE),0) -> 129 | V10: =ifna(VLOOKUP(A10, 'fev25'!$A$132:$B$157, 2, FALSE),0) -> 132.72 | W10: =ifna(VLOOKUP(A10, 'mar25'!$A$125:$B$153, 2, FALSE),0) -> 132.55 | X10: =ifna(VLOOKUP(A10, 'abr25'!$A$131:$B$157, 2, FALSE),0) -> 132.5 | Y10: =ifna(VLOOKUP(A10, 'mai25'!$A$142:$B$174, 2, FALSE),0) -> 132.55 | Z10: =ifna(VLOOKUP(A10, 'jun25'!$A$141:$B$169, 2, FALSE),0) -> 132.76 | AA10: =ifna(VLOOKUP(A10, 'jul25'!$A$141:$B$170, 2, FALSE),0) -> 132.76 | AB10: =ifna(VLOOKUP(A10, 'ago25'!$A$141:$B$170, 2, FALSE),0) -> 132.76 | AC10: =AVERAGE(X10:AA10) -> 132.6425
A11: academia | B11: =Janeiro23!B60 -> 109 | C11: =fevereiro23!B90 -> 109 | D11: =ifna(VLOOKUP(A11, marco23!$A$97:$B$119, 2, FALSE),0) -> 109 | E11: =ifna(VLOOKUP(A11, abril23!$A$82:$B$103, 2, FALSE),0) -> 109 | F11: =ifna(VLOOKUP(A11, maio23!$A$95:$B$117, 2, FALSE),0) -> 109 | G11: =ifna(VLOOKUP(A11, junho23!$A$127:$B$152, 2, FALSE),0) -> 69.9 | H11: =ifna(VLOOKUP(A11, julho23!$A$139:$B$164, 2, FALSE),0) -> 79.9 | I11: =ifna(VLOOKUP(A11, Agosto23!$A$127:$B$152, 2, FALSE),0) -> 286.2 | J11: =ifna(VLOOKUP(A11, setembro23!$A$125:$B$151, 2, FALSE),0) -> 679.8 | K11: =ifna(VLOOKUP(A11, outubro23!$A$121:$B$146, 2, FALSE),0) -> 679.8 | L11: =ifna(VLOOKUP(A11, novembro23!$A$121:$B$146, 2, FALSE),0) -> 679.8 | M11: =ifna(VLOOKUP(A11, Dezembro23!$A$127:$B$152, 2, FALSE),0) -> 679.8 | N11: =ifna(VLOOKUP(A11, janneiro24!$A$127:$B$152, 2, FALSE),0) -> 679.8 | O11: =ifna(VLOOKUP(A11, fevereiro24!$A$127:$B$152, 2, FALSE),0) -> 679.8 | P11: =ifna(VLOOKUP(A11, marco24!$A$127:$B$152, 2, FALSE),0) -> 679.8 | Q11: =ifna(VLOOKUP(A11, abril24!$A$127:$B$152, 2, FALSE),0) -> 679.8 | R11: =ifna(VLOOKUP(A11, maio24!$A$127:$B$152, 2, FALSE),0) -> 679.8 | S11: =ifna(VLOOKUP(A11, 'jun24'!$A$127:$B$152, 2, FALSE),0) -> 679.8 | T11: =ifna(VLOOKUP(A11, 'set24'!$A$127:$B$152, 2, FALSE),0) -> 695.8 | U11: =ifna(VLOOKUP(A11, 'jan25'!$A$127:$B$152, 2, FALSE),0) -> 715.8 | V11: =ifna(VLOOKUP(A11, 'fev25'!$A$132:$B$157, 2, FALSE),0) -> 215.8 | W11: =ifna(VLOOKUP(A11, 'mar25'!$A$125:$B$153, 2, FALSE),0) -> 215.8 | X11: =ifna(VLOOKUP(A11, 'abr25'!$A$131:$B$157, 2, FALSE),0) -> 729.8 | Y11: =ifna(VLOOKUP(A11, 'mai25'!$A$142:$B$174, 2, FALSE),0) -> 729.8 | Z11: =ifna(VLOOKUP(A11, 'jun25'!$A$141:$B$169, 2, FALSE),0) -> 457.96 | AA11: =ifna(VLOOKUP(A11, 'jul25'!$A$141:$B$170, 2, FALSE),0) -> 229.8 | AB11: =ifna(VLOOKUP(A11, 'ago25'!$A$141:$B$170, 2, FALSE),0) -> 229.8 | AC11: =AVERAGE(X11:AA11) -> 536.84
A12: Feira | B12: =Janeiro23!B61 -> 116.74 | C12: =fevereiro23!B82 -> 33 | D12: =ifna(VLOOKUP(A12, marco23!$A$97:$B$119, 2, FALSE),0) -> 34.32 | E12: =ifna(VLOOKUP(A12, abril23!$A$82:$B$103, 2, FALSE),0) -> 59.24 | F12: =ifna(VLOOKUP(A12, maio23!$A$95:$B$117, 2, FALSE),0) -> 0 | G12: =ifna(VLOOKUP(A12, junho23!$A$127:$B$152, 2, FALSE),0) -> 38.2 | H12: =ifna(VLOOKUP(A12, julho23!$A$139:$B$164, 2, FALSE),0) -> 12 | I12: =ifna(VLOOKUP(A12, Agosto23!$A$127:$B$152, 2, FALSE),0) -> 22.2 | J12: =ifna(VLOOKUP(A12, setembro23!$A$125:$B$151, 2, FALSE),0) -> 42.9 | K12: =ifna(VLOOKUP(A12, outubro23!$A$121:$B$146, 2, FALSE),0) -> 16.45 | L12: =ifna(VLOOKUP(A12, novembro23!$A$121:$B$146, 2, FALSE),0) -> 44.9 | M12: =ifna(VLOOKUP(A12, Dezembro23!$A$127:$B$152, 2, FALSE),0) -> 70.95 | N12: =ifna(VLOOKUP(A12, janneiro24!$A$127:$B$152, 2, FALSE),0) -> 0 | O12: =ifna(VLOOKUP(A12, fevereiro24!$A$127:$B$152, 2, FALSE),0) -> 0 | P12: =ifna(VLOOKUP(A12, marco24!$A$127:$B$152, 2, FALSE),0) -> 128.58 | Q12: =ifna(VLOOKUP(A12, abril24!$A$127:$B$152, 2, FALSE),0) -> 65.2 | R12: =ifna(VLOOKUP(A12, maio24!$A$127:$B$152, 2, FALSE),0) -> 169.12 | S12: =ifna(VLOOKUP(A12, 'jun24'!$A$127:$B$152, 2, FALSE),0) -> 161.05 | T12: =ifna(VLOOKUP(A12, 'set24'!$A$127:$B$152, 2, FALSE),0) -> 31 | U12: =ifna(VLOOKUP(A12, 'jan25'!$A$127:$B$152, 2, FALSE),0) -> 0 | V12: =ifna(VLOOKUP(A12, 'fev25'!$A$132:$B$157, 2, FALSE),0) -> 183.88 | W12: =ifna(VLOOKUP(A12, 'mar25'!$A$125:$B$153, 2, FALSE),0) -> 125.68 | X12: =ifna(VLOOKUP(A12, 'abr25'!$A$131:$B$157, 2, FALSE),0) -> 177.18 | Y12: =ifna(VLOOKUP(A12, 'mai25'!$A$142:$B$174, 2, FALSE),0) -> 310.15 | Z12: =ifna(VLOOKUP(A12, 'jun25'!$A$141:$B$169, 2, FALSE),0) -> 144.27 | AA12: =ifna(VLOOKUP(A12, 'jul25'!$A$141:$B$170, 2, FALSE),0) -> 217.82 | AB12: =ifna(VLOOKUP(A12, 'ago25'!$A$141:$B$170, 2, FALSE),0) -> 189.09 | AC12: =AVERAGE(X12:AA12) -> 212.355
A13: farmacia | B13: =Janeiro23!B62 -> 185.46 | C13: =0 -> 0 | D13: =ifna(VLOOKUP(A13, marco23!$A$97:$B$119, 2, FALSE),0) -> 150.32 | E13: =ifna(VLOOKUP(A13, abril23!$A$82:$B$103, 2, FALSE),0) -> 101.66 | F13: =ifna(VLOOKUP(A13, maio23!$A$95:$B$117, 2, FALSE),0) -> 168.62 | G13: =ifna(VLOOKUP(A13, junho23!$A$127:$B$152, 2, FALSE),0) -> 285.67 | H13: =ifna(VLOOKUP(A13, julho23!$A$139:$B$164, 2, FALSE),0) -> 67.23 | I13: =ifna(VLOOKUP(A13, Agosto23!$A$127:$B$152, 2, FALSE),0) -> 124.96 | J13: =ifna(VLOOKUP(A13, setembro23!$A$125:$B$151, 2, FALSE),0) -> 0 | K13: =ifna(VLOOKUP(A13, outubro23!$A$121:$B$146, 2, FALSE),0) -> 106.54 | L13: =ifna(VLOOKUP(A13, novembro23!$A$121:$B$146, 2, FALSE),0) -> 52.66 | M13: =ifna(VLOOKUP(A13, Dezembro23!$A$127:$B$152, 2, FALSE),0) -> 0 | N13: =ifna(VLOOKUP(A13, janneiro24!$A$127:$B$152, 2, FALSE),0) -> 60.48 | O13: =ifna(VLOOKUP(A13, fevereiro24!$A$127:$B$152, 2, FALSE),0) -> 60.48 | P13: =ifna(VLOOKUP(A13, marco24!$A$127:$B$152, 2, FALSE),0) -> 67.49 | Q13: =ifna(VLOOKUP(A13, abril24!$A$127:$B$152, 2, FALSE),0) -> 132.1 | R13: =ifna(VLOOKUP(A13, maio24!$A$127:$B$152, 2, FALSE),0) -> 34.17 | S13: =ifna(VLOOKUP(A13, 'jun24'!$A$127:$B$152, 2, FALSE),0) -> 167.73 | T13: =ifna(VLOOKUP(A13, 'set24'!$A$127:$B$152, 2, FALSE),0) -> 69.54 | U13: =ifna(VLOOKUP(A13, 'jan25'!$A$127:$B$152, 2, FALSE),0) -> 140 | V13: =ifna(VLOOKUP(A13, 'fev25'!$A$132:$B$157, 2, FALSE),0) -> 25.33 | W13: =ifna(VLOOKUP(A13, 'mar25'!$A$125:$B$153, 2, FALSE),0) -> 79.88 | X13: =ifna(VLOOKUP(A13, 'abr25'!$A$131:$B$157, 2, FALSE),0) -> 171.34 | Y13: =ifna(VLOOKUP(A13, 'mai25'!$A$142:$B$174, 2, FALSE),0) -> 167.34 | Z13: =ifna(VLOOKUP(A13, 'jun25'!$A$141:$B$169, 2, FALSE),0) -> 49.98 | AA13: =ifna(VLOOKUP(A13, 'jul25'!$A$141:$B$170, 2, FALSE),0) -> 71.97 | AB13: =ifna(VLOOKUP(A13, 'ago25'!$A$141:$B$170, 2, FALSE),0) -> 69.89 | AC13: =AVERAGE(X13:AA13) -> 115.1575
A14: seguro | B14: =Janeiro23!B63 -> 206.99 | C14: =fevereiro23!B93 -> 206.99 | D14: =ifna(VLOOKUP(A14, marco23!$A$97:$B$119, 2, FALSE),0) -> 206.99 | E14: =ifna(VLOOKUP(A14, abril23!$A$82:$B$103, 2, FALSE),0) -> 206.99 | F14: =ifna(VLOOKUP(A14, maio23!$A$95:$B$117, 2, FALSE),0) -> 206.99 | G14: =ifna(VLOOKUP(A14, junho23!$A$127:$B$152, 2, FALSE),0) -> 206.99 | H14: =ifna(VLOOKUP(A14, julho23!$A$139:$B$164, 2, FALSE),0) -> 206.99 | I14: =ifna(VLOOKUP(A14, Agosto23!$A$127:$B$152, 2, FALSE),0) -> 218.5 | J14: =ifna(VLOOKUP(A14, setembro23!$A$125:$B$151, 2, FALSE),0) -> 218.5 | K14: =ifna(VLOOKUP(A14, outubro23!$A$121:$B$146, 2, FALSE),0) -> 218.5 | L14: =ifna(VLOOKUP(A14, novembro23!$A$121:$B$146, 2, FALSE),0) -> 218.5 | M14: =ifna(VLOOKUP(A14, Dezembro23!$A$127:$B$152, 2, FALSE),0) -> 218.5 | N14: =ifna(VLOOKUP(A14, janneiro24!$A$127:$B$152, 2, FALSE),0) -> 218.5 | O14: =ifna(VLOOKUP(A14, fevereiro24!$A$127:$B$152, 2, FALSE),0) -> 218.5 | P14: =ifna(VLOOKUP(A14, marco24!$A$127:$B$152, 2, FALSE),0) -> 218.5 | Q14: =ifna(VLOOKUP(A14, abril24!$A$127:$B$152, 2, FALSE),0) -> 218.5 | R14: =ifna(VLOOKUP(A14, maio24!$A$127:$B$152, 2, FALSE),0) -> 218.5 | S14: =ifna(VLOOKUP(A14, 'jun24'!$A$127:$B$152, 2, FALSE),0) -> 218.5 | T14: =ifna(VLOOKUP(A14, 'set24'!$A$127:$B$152, 2, FALSE),0) -> 218.5 | U14: =ifna(VLOOKUP(A14, 'jan25'!$A$127:$B$152, 2, FALSE),0) -> 244.12 | V14: =ifna(VLOOKUP(A14, 'fev25'!$A$132:$B$157, 2, FALSE),0) -> 244.12 | W14: =ifna(VLOOKUP(A14, 'mar25'!$A$125:$B$153, 2, FALSE),0) -> 244.12 | X14: =ifna(VLOOKUP(A14, 'abr25'!$A$131:$B$157, 2, FALSE),0) -> 244.12 | Y14: =ifna(VLOOKUP(A14, 'mai25'!$A$142:$B$174, 2, FALSE),0) -> 244.12 | Z14: =ifna(VLOOKUP(A14, 'jun25'!$A$141:$B$169, 2, FALSE),0) -> 244.12 | AA14: =ifna(VLOOKUP(A14, 'jul25'!$A$141:$B$170, 2, FALSE),0) -> 244.12 | AB14: =ifna(VLOOKUP(A14, 'ago25'!$A$141:$B$170, 2, FALSE),0) -> 244.12 | AC14: =AVERAGE(X14:AA14) -> 244.12
A15: Energia | B15: =Janeiro23!B64 -> 450 | C15: =fevereiro23!B98 -> 510 | D15: =ifna(VLOOKUP(A15, marco23!$A$97:$B$119, 2, FALSE),0) -> 0 | E15: =ifna(VLOOKUP(A15, abril23!$A$82:$B$103, 2, FALSE),0) -> 1169.2 | F15: =ifna(VLOOKUP(A15, maio23!$A$95:$B$117, 2, FALSE),0) -> 550 | G15: =ifna(VLOOKUP(A15, junho23!$A$127:$B$152, 2, FALSE),0) -> 511 | H15: =ifna(VLOOKUP(A15, julho23!$A$139:$B$164, 2, FALSE),0) -> 511 | I15: =ifna(VLOOKUP(A15, Agosto23!$A$127:$B$152, 2, FALSE),0) -> 511 | J15: =ifna(VLOOKUP(A15, setembro23!$A$125:$B$151, 2, FALSE),0) -> 511 | K15: =ifna(VLOOKUP(A15, outubro23!$A$121:$B$146, 2, FALSE),0) -> 407 | L15: =ifna(VLOOKUP(A15, novembro23!$A$121:$B$146, 2, FALSE),0) -> 333.32 | M15: =ifna(VLOOKUP(A15, Dezembro23!$A$127:$B$152, 2, FALSE),0) -> 333.32 | N15: =ifna(VLOOKUP(A15, janneiro24!$A$127:$B$152, 2, FALSE),0) -> 333.32 | O15: =ifna(VLOOKUP(A15, fevereiro24!$A$127:$B$152, 2, FALSE),0) -> 800 | P15: =ifna(VLOOKUP(A15, marco24!$A$127:$B$152, 2, FALSE),0) -> 696.36 | Q15: =ifna(VLOOKUP(A15, abril24!$A$127:$B$152, 2, FALSE),0) -> 696.36 | R15: =ifna(VLOOKUP(A15, maio24!$A$127:$B$152, 2, FALSE),0) -> 696.36 | S15: =ifna(VLOOKUP(A15, 'jun24'!$A$127:$B$152, 2, FALSE),0) -> 696.36 | T15: =ifna(VLOOKUP(A15, 'set24'!$A$127:$B$152, 2, FALSE),0) -> 521.44 | U15: =ifna(VLOOKUP(A15, 'jan25'!$A$127:$B$152, 2, FALSE),0) -> 600 | V15: =ifna(VLOOKUP(A15, 'fev25'!$A$132:$B$157, 2, FALSE),0) -> 1160.14 | W15: =ifna(VLOOKUP(A15, 'mar25'!$A$125:$B$153, 2, FALSE),0) -> 0 | X15: =ifna(VLOOKUP(A15, 'abr25'!$A$131:$B$157, 2, FALSE),0) -> 600 | Y15: =ifna(VLOOKUP(A15, 'mai25'!$A$142:$B$174, 2, FALSE),0) -> 0 | Z15: =ifna(VLOOKUP(A15, 'jun25'!$A$141:$B$169, 2, FALSE),0) -> 356.67 | AA15: =ifna(VLOOKUP(A15, 'jul25'!$A$141:$B$170, 2, FALSE),0) -> 60 | AB15: =ifna(VLOOKUP(A15, 'ago25'!$A$141:$B$170, 2, FALSE),0) -> 118 | AC15: =AVERAGE(X15:AA15) -> 254.1675
A16: Pet | B16: =Janeiro23!B65 -> 544.55 | C16: =fevereiro23!B100 -> 772.97 | D16: =ifna(VLOOKUP(A16, marco23!$A$97:$B$119, 2, FALSE),0) -> 1115.05 | E16: =ifna(VLOOKUP(A16, abril23!$A$82:$B$103, 2, FALSE),0) -> 245.93 | F16: =ifna(VLOOKUP(A16, maio23!$A$95:$B$117, 2, FALSE),0) -> 1479.63 | G16: =ifna(VLOOKUP(A16, junho23!$A$127:$B$152, 2, FALSE),0) -> 2191.3 | H16: =ifna(VLOOKUP(A16, julho23!$A$139:$B$164, 2, FALSE),0) -> 2149.4 | I16: =ifna(VLOOKUP(A16, Agosto23!$A$127:$B$152, 2, FALSE),0) -> 623.87 | J16: =ifna(VLOOKUP(A16, setembro23!$A$125:$B$151, 2, FALSE),0) -> 1524.37 | K16: =ifna(VLOOKUP(A16, outubro23!$A$121:$B$146, 2, FALSE),0) -> 1903.49 | L16: =ifna(VLOOKUP(A16, novembro23!$A$121:$B$146, 2, FALSE),0) -> 860.2 | M16: =ifna(VLOOKUP(A16, Dezembro23!$A$127:$B$152, 2, FALSE),0) -> 3924.91 | N16: =ifna(VLOOKUP(A16, janneiro24!$A$127:$B$152, 2, FALSE),0) -> 5503.4 | O16: =ifna(VLOOKUP(A16, fevereiro24!$A$127:$B$152, 2, FALSE),0) -> 5503.4 | P16: =ifna(VLOOKUP(A16, marco24!$A$127:$B$152, 2, FALSE),0) -> 878.65 | Q16: =ifna(VLOOKUP(A16, abril24!$A$127:$B$152, 2, FALSE),0) -> 528.22 | R16: =ifna(VLOOKUP(A16, maio24!$A$127:$B$152, 2, FALSE),0) -> 1465.67 | S16: =ifna(VLOOKUP(A16, 'jun24'!$A$127:$B$152, 2, FALSE),0) -> 109.6 | T16: =ifna(VLOOKUP(A16, 'set24'!$A$127:$B$152, 2, FALSE),0) -> 919.52 | U16: =ifna(VLOOKUP(A16, 'jan25'!$A$127:$B$152, 2, FALSE),0) -> 0 | V16: =ifna(VLOOKUP(A16, 'fev25'!$A$132:$B$157, 2, FALSE),0) -> 697.2 | W16: =ifna(VLOOKUP(A16, 'mar25'!$A$125:$B$153, 2, FALSE),0) -> 1175.52 | X16: =ifna(VLOOKUP(A16, 'abr25'!$A$131:$B$157, 2, FALSE),0) -> 1194.88 | Y16: =ifna(VLOOKUP(A16, 'mai25'!$A$142:$B$174, 2, FALSE),0) -> 468.61 | Z16: =ifna(VLOOKUP(A16, 'jun25'!$A$141:$B$169, 2, FALSE),0) -> 771.5 | AA16: =ifna(VLOOKUP(A16, 'jul25'!$A$141:$B$170, 2, FALSE),0) -> 1370.74 | AB16: =ifna(VLOOKUP(A16, 'ago25'!$A$141:$B$170, 2, FALSE),0) -> 1214.68 | AC16: =AVERAGE(X16:AA16) -> 951.4325
A17: mercado | B17: =Janeiro23!B68 -> 1228.08 | C17: =fevereiro23!B99 -> 585.69 | D17: =ifna(VLOOKUP(A17, marco23!$A$97:$B$119, 2, FALSE),0) -> 1025.47 | E17: =ifna(VLOOKUP(A17, abril23!$A$82:$B$103, 2, FALSE),0) -> 648.42 | F17: =ifna(VLOOKUP(A17, maio23!$A$95:$B$117, 2, FALSE),0) -> 1382.2 | G17: =ifna(VLOOKUP(A17, junho23!$A$127:$B$152, 2, FALSE),0) -> 1493.65 | H17: =ifna(VLOOKUP(A17, julho23!$A$139:$B$164, 2, FALSE),0) -> 1015.78 | I17: =ifna(VLOOKUP(A17, Agosto23!$A$127:$B$152, 2, FALSE),0) -> 1151.82 | J17: =ifna(VLOOKUP(A17, setembro23!$A$125:$B$151, 2, FALSE),0) -> 1202.85 | K17: =ifna(VLOOKUP(A17, outubro23!$A$121:$B$146, 2, FALSE),0) -> 1284.31 | L17: =ifna(VLOOKUP(A17, novembro23!$A$121:$B$146, 2, FALSE),0) -> 1069.75 | M17: =ifna(VLOOKUP(A17, Dezembro23!$A$127:$B$152, 2, FALSE),0) -> 736.04 | N17: =ifna(VLOOKUP(A17, janneiro24!$A$127:$B$152, 2, FALSE),0) -> 269.24 | O17: =ifna(VLOOKUP(A17, fevereiro24!$A$127:$B$152, 2, FALSE),0) -> 269.24 | P17: =ifna(VLOOKUP(A17, marco24!$A$127:$B$152, 2, FALSE),0) -> 1213.51 | Q17: =ifna(VLOOKUP(A17, abril24!$A$127:$B$152, 2, FALSE),0) -> 1143.95 | R17: =ifna(VLOOKUP(A17, maio24!$A$127:$B$152, 2, FALSE),0) -> 1473.36 | S17: =ifna(VLOOKUP(A17, 'jun24'!$A$127:$B$152, 2, FALSE),0) -> 720.21 | T17: =ifna(VLOOKUP(A17, 'set24'!$A$127:$B$152, 2, FALSE),0) -> 558.25 | U17: =ifna(VLOOKUP(A17, 'jan25'!$A$127:$B$152, 2, FALSE),0) -> 0 | V17: =ifna(VLOOKUP(A17, 'fev25'!$A$132:$B$157, 2, FALSE),0) -> 1423.03 | W17: =ifna(VLOOKUP(A17, 'mar25'!$A$125:$B$153, 2, FALSE),0) -> 993.2 | X17: =ifna(VLOOKUP(A17, 'abr25'!$A$131:$B$157, 2, FALSE),0) -> 1177.36 | Y17: =ifna(VLOOKUP(A17, 'mai25'!$A$142:$B$174, 2, FALSE),0) -> 1670.69 | Z17: =ifna(VLOOKUP(A17, 'jun25'!$A$141:$B$169, 2, FALSE),0) -> 1179.08 | AA17: =ifna(VLOOKUP(A17, 'jul25'!$A$141:$B$170, 2, FALSE),0) -> 1083.14 | AB17: =ifna(VLOOKUP(A17, 'ago25'!$A$141:$B$170, 2, FALSE),0) -> 1151.27 | AC17: =AVERAGE(X17:AA17) -> 1277.5675
A18: Cabeleireiro | B18: =0 -> 0 | C18: =fevereiro23!B84 -> 38 | D18: =ifna(VLOOKUP(A18, marco23!$A$97:$B$119, 2, FALSE),0) -> 0 | E18: =ifna(VLOOKUP(A18, abril23!$A$82:$B$103, 2, FALSE),0) -> 0 | F18: =ifna(VLOOKUP(A18, maio23!$A$95:$B$117, 2, FALSE),0) -> 0 | G18: =ifna(VLOOKUP(A18, junho23!$A$127:$B$152, 2, FALSE),0) -> 0 | H18: =ifna(VLOOKUP(A18, julho23!$A$139:$B$164, 2, FALSE),0) -> 0 | I18: =ifna(VLOOKUP(A18, Agosto23!$A$127:$B$152, 2, FALSE),0) -> 0 | J18: =ifna(VLOOKUP(A18, setembro23!$A$125:$B$151, 2, FALSE),0) -> 0 | K18: =ifna(VLOOKUP(A18, outubro23!$A$121:$B$146, 2, FALSE),0) -> 0 | L18: =ifna(VLOOKUP(A18, novembro23!$A$121:$B$146, 2, FALSE),0) -> 0 | M18: =ifna(VLOOKUP(A18, Dezembro23!$A$127:$B$152, 2, FALSE),0) -> 55 | N18: =ifna(VLOOKUP(A18, janneiro24!$A$127:$B$152, 2, FALSE),0) -> 0 | O18: =ifna(VLOOKUP(A18, fevereiro24!$A$127:$B$152, 2, FALSE),0) -> 0 | P18: =ifna(VLOOKUP(A18, marco24!$A$127:$B$152, 2, FALSE),0) -> 0 | Q18: =ifna(VLOOKUP(A18, abril24!$A$127:$B$152, 2, FALSE),0) -> 105 | R18: =ifna(VLOOKUP(A18, maio24!$A$127:$B$152, 2, FALSE),0) -> 0 | S18: =ifna(VLOOKUP(A18, 'jun24'!$A$127:$B$152, 2, FALSE),0) -> 0 | T18: =ifna(VLOOKUP(A18, 'set24'!$A$127:$B$152, 2, FALSE),0) -> 0 | U18: =ifna(VLOOKUP(A18, 'jan25'!$A$127:$B$152, 2, FALSE),0) -> 0 | V18: =ifna(VLOOKUP(A18, 'fev25'!$A$132:$B$157, 2, FALSE),0) -> 0 | W18: =ifna(VLOOKUP(A18, 'mar25'!$A$125:$B$153, 2, FALSE),0) -> 40 | X18: =ifna(VLOOKUP(A18, 'abr25'!$A$131:$B$157, 2, FALSE),0) -> 0 | Y18: =ifna(VLOOKUP(A18, 'mai25'!$A$142:$B$174, 2, FALSE),0) -> 0 | Z18: =ifna(VLOOKUP(A18, 'jun25'!$A$141:$B$169, 2, FALSE),0) -> 40 | AA18: =ifna(VLOOKUP(A18, 'jul25'!$A$141:$B$170, 2, FALSE),0) -> 0 | AB18: =ifna(VLOOKUP(A18, 'ago25'!$A$141:$B$170, 2, FALSE),0) -> 0 | AC18: =AVERAGE(X18:AA18) -> 10
A19: Vestuario | B19: =0 -> 0 | C19: =fevereiro23!B87 -> 89.99 | D19: =ifna(VLOOKUP(A19, marco23!$A$97:$B$119, 2, FALSE),0) -> 274.92 | E19: =ifna(VLOOKUP(A19, abril23!$A$82:$B$103, 2, FALSE),0) -> 0 | F19: =ifna(VLOOKUP(A19, maio23!$A$95:$B$117, 2, FALSE),0) -> 266.14 | G19: =ifna(VLOOKUP(A19, junho23!$A$127:$B$152, 2, FALSE),0) -> 0 | H19: =ifna(VLOOKUP(A19, julho23!$A$139:$B$164, 2, FALSE),0) -> 29.99 | I19: =ifna(VLOOKUP(A19, Agosto23!$A$127:$B$152, 2, FALSE),0) -> 0 | J19: =ifna(VLOOKUP(A19, setembro23!$A$125:$B$151, 2, FALSE),0) -> 121.42 | K19: =ifna(VLOOKUP(A19, outubro23!$A$121:$B$146, 2, FALSE),0) -> 149.99 | L19: =ifna(VLOOKUP(A19, novembro23!$A$121:$B$146, 2, FALSE),0) -> 460.99 | M19: =ifna(VLOOKUP(A19, Dezembro23!$A$127:$B$152, 2, FALSE),0) -> 569.87 | N19: =ifna(VLOOKUP(A19, janneiro24!$A$127:$B$152, 2, FALSE),0) -> 109.95 | O19: =ifna(VLOOKUP(A19, fevereiro24!$A$127:$B$152, 2, FALSE),0) -> 109.95 | P19: =ifna(VLOOKUP(A19, marco24!$A$127:$B$152, 2, FALSE),0) -> 280.87 | Q19: =ifna(VLOOKUP(A19, abril24!$A$127:$B$152, 2, FALSE),0) -> 84.9 | R19: =ifna(VLOOKUP(A19, maio24!$A$127:$B$152, 2, FALSE),0) -> 386.68 | S19: =ifna(VLOOKUP(A19, 'jun24'!$A$127:$B$152, 2, FALSE),0) -> 204.69 | T19: =ifna(VLOOKUP(A19, 'set24'!$A$127:$B$152, 2, FALSE),0) -> 0 | U19: =ifna(VLOOKUP(A19, 'jan25'!$A$127:$B$152, 2, FALSE),0) -> 0 | V19: =ifna(VLOOKUP(A19, 'fev25'!$A$132:$B$157, 2, FALSE),0) -> 0 | W19: =ifna(VLOOKUP(A19, 'mar25'!$A$125:$B$153, 2, FALSE),0) -> 324.93 | X19: =ifna(VLOOKUP(A19, 'abr25'!$A$131:$B$157, 2, FALSE),0) -> 305.69 | Y19: =ifna(VLOOKUP(A19, 'mai25'!$A$142:$B$174, 2, FALSE),0) -> 199.96 | Z19: =ifna(VLOOKUP(A19, 'jun25'!$A$141:$B$169, 2, FALSE),0) -> 164.97 | AA19: =ifna(VLOOKUP(A19, 'jul25'!$A$141:$B$170, 2, FALSE),0) -> 364.93 | AB19: =ifna(VLOOKUP(A19, 'ago25'!$A$141:$B$170, 2, FALSE),0) -> 968.53 | AC19: =AVERAGE(X19:AA19) -> 258.8875
A20: outros | B20: =0 -> 0 | C20: =fevereiro23!B92 -> 200 | D20: =ifna(VLOOKUP(A20, marco23!$A$97:$B$119, 2, FALSE),0) -> 0 | E20: =ifna(VLOOKUP(A20, abril23!$A$82:$B$103, 2, FALSE),0) -> 100 | F20: =ifna(VLOOKUP(A20, maio23!$A$95:$B$117, 2, FALSE),0) -> 0 | G20: =ifna(VLOOKUP(A20, junho23!$A$127:$B$152, 2, FALSE),0) -> 0 | H20: =ifna(VLOOKUP(A20, julho23!$A$139:$B$164, 2, FALSE),0) -> 0 | I20: =ifna(VLOOKUP(A20, Agosto23!$A$127:$B$152, 2, FALSE),0) -> 100 | J20: =ifna(VLOOKUP(A20, setembro23!$A$125:$B$151, 2, FALSE),0) -> 175.54 | K20: =ifna(VLOOKUP(A20, outubro23!$A$121:$B$146, 2, FALSE),0) -> 156.9 | L20: =ifna(VLOOKUP(A20, novembro23!$A$121:$B$146, 2, FALSE),0) -> 385.26 | M20: =ifna(VLOOKUP(A20, Dezembro23!$A$127:$B$152, 2, FALSE),0) -> 525.9 | N20: =ifna(VLOOKUP(A20, janneiro24!$A$127:$B$152, 2, FALSE),0) -> 0 | O20: =ifna(VLOOKUP(A20, fevereiro24!$A$127:$B$152, 2, FALSE),0) -> 0 | P20: =ifna(VLOOKUP(A20, marco24!$A$127:$B$152, 2, FALSE),0) -> 215.36 | Q20: =ifna(VLOOKUP(A20, abril24!$A$127:$B$152, 2, FALSE),0) -> 89.99 | R20: =ifna(VLOOKUP(A20, maio24!$A$127:$B$152, 2, FALSE),0) -> 257.43 | S20: =ifna(VLOOKUP(A20, 'jun24'!$A$127:$B$152, 2, FALSE),0) -> 40.99 | T20: =ifna(VLOOKUP(A20, 'set24'!$A$127:$B$152, 2, FALSE),0) -> 41 | U20: =ifna(VLOOKUP(A20, 'jan25'!$A$127:$B$152, 2, FALSE),0) -> 0 | V20: =ifna(VLOOKUP(A20, 'fev25'!$A$132:$B$157, 2, FALSE),0) -> 282.25 | W20: =ifna(VLOOKUP(A20, 'mar25'!$A$125:$B$153, 2, FALSE),0) -> 814.77 | X20: =ifna(VLOOKUP(A20, 'abr25'!$A$131:$B$157, 2, FALSE),0) -> 406.27 | Y20: =ifna(VLOOKUP(A20, 'mai25'!$A$142:$B$174, 2, FALSE),0) -> 108.44 | Z20: =ifna(VLOOKUP(A20, 'jun25'!$A$141:$B$169, 2, FALSE),0) -> 631.82 | AA20: =ifna(VLOOKUP(A20, 'jul25'!$A$141:$B$170, 2, FALSE),0) -> 40 | AB20: =ifna(VLOOKUP(A20, 'ago25'!$A$141:$B$170, 2, FALSE),0) -> 153.71 | AC20: =AVERAGE(X20:AA20) -> 296.6325
A21: utilizades domesticas | B21: 0 | C21: =fevereiro23!B94 -> 261.83 | D21: =ifna(VLOOKUP(A21, marco23!$A$97:$B$119, 2, FALSE),0) -> 139.07 | E21: =ifna(VLOOKUP(A21, abril23!$A$82:$B$103, 2, FALSE),0) -> 142.18 | F21: =ifna(VLOOKUP(A21, maio23!$A$95:$B$117, 2, FALSE),0) -> 0 | G21: =ifna(VLOOKUP(A21, junho23!$A$127:$B$152, 2, FALSE),0) -> 0 | H21: =ifna(VLOOKUP(A21, julho23!$A$139:$B$164, 2, FALSE),0) -> 86.08 | I21: =ifna(VLOOKUP(A21, Agosto23!$A$127:$B$152, 2, FALSE),0) -> 226.33 | J21: =ifna(VLOOKUP(A21, setembro23!$A$125:$B$151, 2, FALSE),0) -> 180 | K21: =ifna(VLOOKUP(A21, outubro23!$A$121:$B$146, 2, FALSE),0) -> 252.36 | L21: =ifna(VLOOKUP(A21, novembro23!$A$121:$B$146, 2, FALSE),0) -> 0 | M21: =ifna(VLOOKUP(A21, Dezembro23!$A$127:$B$152, 2, FALSE),0) -> 25.99 | N21: =ifna(VLOOKUP(A21, janneiro24!$A$127:$B$152, 2, FALSE),0) -> 0 | O21: =ifna(VLOOKUP(A21, fevereiro24!$A$127:$B$152, 2, FALSE),0) -> 0 | P21: =ifna(VLOOKUP(A21, marco24!$A$127:$B$152, 2, FALSE),0) -> 0 | Q21: =ifna(VLOOKUP(A21, abril24!$A$127:$B$152, 2, FALSE),0) -> 0 | R21: =ifna(VLOOKUP(A21, maio24!$A$127:$B$152, 2, FALSE),0) -> 0 | S21: =ifna(VLOOKUP(A21, 'jun24'!$A$127:$B$152, 2, FALSE),0) -> 0 | T21: =ifna(VLOOKUP(A21, 'set24'!$A$127:$B$152, 2, FALSE),0) -> 0 | U21: =ifna(VLOOKUP(A21, 'jan25'!$A$127:$B$152, 2, FALSE),0) -> 0 | V21: =ifna(VLOOKUP(A21, 'fev25'!$A$132:$B$157, 2, FALSE),0) -> 33.5 | W21: =ifna(VLOOKUP(A21, 'mar25'!$A$125:$B$153, 2, FALSE),0) -> 96.4 | X21: =ifna(VLOOKUP(A21, 'abr25'!$A$131:$B$157, 2, FALSE),0) -> 180.87 | Y21: =ifna(VLOOKUP(A21, 'mai25'!$A$142:$B$174, 2, FALSE),0) -> 32.86 | Z21: =ifna(VLOOKUP(A21, 'jun25'!$A$141:$B$169, 2, FALSE),0) -> 17.94 | AA21: =ifna(VLOOKUP(A21, 'jul25'!$A$141:$B$170, 2, FALSE),0) -> 0 | AB21: =ifna(VLOOKUP(A21, 'ago25'!$A$141:$B$170, 2, FALSE),0) -> 0 | AC21: =AVERAGE(X21:AA21) -> 57.9175
A22: Lazer | B22: 0 | C22: =fevereiro23!B96 -> 454.76 | D22: =ifna(VLOOKUP(A22, marco23!$A$97:$B$119, 2, FALSE),0) -> 443.82 | E22: =ifna(VLOOKUP(A22, abril23!$A$82:$B$103, 2, FALSE),0) -> 155.1 | F22: =ifna(VLOOKUP(A22, maio23!$A$95:$B$117, 2, FALSE),0) -> 371.54 | G22: =ifna(VLOOKUP(A22, junho23!$A$127:$B$152, 2, FALSE),0) -> 515.7 | H22: =ifna(VLOOKUP(A22, julho23!$A$139:$B$164, 2, FALSE),0) -> 142.9 | I22: =ifna(VLOOKUP(A22, Agosto23!$A$127:$B$152, 2, FALSE),0) -> 655.65 | J22: =ifna(VLOOKUP(A22, setembro23!$A$125:$B$151, 2, FALSE),0) -> 199.6 | K22: =ifna(VLOOKUP(A22, outubro23!$A$121:$B$146, 2, FALSE),0) -> 423.42 | L22: =ifna(VLOOKUP(A22, novembro23!$A$121:$B$146, 2, FALSE),0) -> 457.02 | M22: =ifna(VLOOKUP(A22, Dezembro23!$A$127:$B$152, 2, FALSE),0) -> 414.68 | N22: =ifna(VLOOKUP(A22, janneiro24!$A$127:$B$152, 2, FALSE),0) -> 90 | O22: =ifna(VLOOKUP(A22, fevereiro24!$A$127:$B$152, 2, FALSE),0) -> 90 | P22: =ifna(VLOOKUP(A22, marco24!$A$127:$B$152, 2, FALSE),0) -> 90 | Q22: =ifna(VLOOKUP(A22, abril24!$A$127:$B$152, 2, FALSE),0) -> 357.45 | R22: =ifna(VLOOKUP(A22, maio24!$A$127:$B$152, 2, FALSE),0) -> 209.7 | S22: =ifna(VLOOKUP(A22, 'jun24'!$A$127:$B$152, 2, FALSE),0) -> 636.16 | T22: =ifna(VLOOKUP(A22, 'set24'!$A$127:$B$152, 2, FALSE),0) -> 169.9 | U22: =ifna(VLOOKUP(A22, 'jan25'!$A$127:$B$152, 2, FALSE),0) -> 60 | V22: =ifna(VLOOKUP(A22, 'fev25'!$A$132:$B$157, 2, FALSE),0) -> 546.88 | W22: =ifna(VLOOKUP(A22, 'mar25'!$A$125:$B$153, 2, FALSE),0) -> 282.49 | X22: =ifna(VLOOKUP(A22, 'abr25'!$A$131:$B$157, 2, FALSE),0) -> 354.38 | Y22: =ifna(VLOOKUP(A22, 'mai25'!$A$142:$B$174, 2, FALSE),0) -> 294.93 | Z22: =ifna(VLOOKUP(A22, 'jun25'!$A$141:$B$169, 2, FALSE),0) -> 768.33 | AA22: =ifna(VLOOKUP(A22, 'jul25'!$A$141:$B$170, 2, FALSE),0) -> 847.76 | AB22: =ifna(VLOOKUP(A22, 'ago25'!$A$141:$B$170, 2, FALSE),0) -> 1320.52 | AC22: =AVERAGE(X22:AA22) -> 566.35
A23: material escolar | B23: =0 -> 0 | C23: =fevereiro23!B101 -> 829.1 | D23: =ifna(VLOOKUP(A23, marco23!$A$97:$B$119, 2, FALSE),0) -> 737 | E23: =ifna(VLOOKUP(A23, abril23!$A$82:$B$103, 2, FALSE),0) -> 33.47 | F23: =ifna(VLOOKUP(A23, maio23!$A$95:$B$117, 2, FALSE),0) -> 32.94 | G23: =ifna(VLOOKUP(A23, junho23!$A$127:$B$152, 2, FALSE),0) -> 8.46 | H23: =ifna(VLOOKUP(A23, julho23!$A$139:$B$164, 2, FALSE),0) -> 0 | I23: =ifna(VLOOKUP(A23, Agosto23!$A$127:$B$152, 2, FALSE),0) -> 125.12 | J23: =ifna(VLOOKUP(A23, setembro23!$A$125:$B$151, 2, FALSE),0) -> 0 | K23: =ifna(VLOOKUP(A23, outubro23!$A$121:$B$146, 2, FALSE),0) -> 0 | L23: =ifna(VLOOKUP(A23, novembro23!$A$121:$B$146, 2, FALSE),0) -> 0 | M23: =ifna(VLOOKUP(A23, Dezembro23!$A$127:$B$152, 2, FALSE),0) -> 0 | N23: =ifna(VLOOKUP(A23, janneiro24!$A$127:$B$152, 2, FALSE),0) -> 0 | O23: =ifna(VLOOKUP(A23, fevereiro24!$A$127:$B$152, 2, FALSE),0) -> 0 | P23: =ifna(VLOOKUP(A23, marco24!$A$127:$B$152, 2, FALSE),0) -> 0 | Q23: =ifna(VLOOKUP(A23, abril24!$A$127:$B$152, 2, FALSE),0) -> 0 | R23: =ifna(VLOOKUP(A23, maio24!$A$127:$B$152, 2, FALSE),0) -> 0 | S23: =ifna(VLOOKUP(A23, 'jun24'!$A$127:$B$152, 2, FALSE),0) -> 0 | T23: =ifna(VLOOKUP(A23, 'set24'!$A$127:$B$152, 2, FALSE),0) -> 0 | U23: =ifna(VLOOKUP(A23, 'jan25'!$A$127:$B$152, 2, FALSE),0) -> 0 | V23: =ifna(VLOOKUP(A23, 'fev25'!$A$132:$B$157, 2, FALSE),0) -> 1638 | W23: =ifna(VLOOKUP(A23, 'mar25'!$A$125:$B$153, 2, FALSE),0) -> 0 | X23: =ifna(VLOOKUP(A23, 'abr25'!$A$131:$B$157, 2, FALSE),0) -> 0 | Y23: =ifna(VLOOKUP(A23, 'mai25'!$A$142:$B$174, 2, FALSE),0) -> 48.73 | Z23: =ifna(VLOOKUP(A23, 'jun25'!$A$141:$B$169, 2, FALSE),0) -> 0 | AA23: =ifna(VLOOKUP(A23, 'jul25'!$A$141:$B$170, 2, FALSE),0) -> 39.97 | AB23: =ifna(VLOOKUP(A23, 'ago25'!$A$141:$B$170, 2, FALSE),0) -> 26.5 | AC23: =AVERAGE(X23:AA23) -> 22.175
A24: Uber | B24: =0 -> 0 | C24: =0 -> 0 | D24: =ifna(VLOOKUP(A24, marco23!$A$97:$B$119, 2, FALSE),0) -> 40.83 | E24: =ifna(VLOOKUP(A24, abril23!$A$82:$B$103, 2, FALSE),0) -> 0 | F24: =ifna(VLOOKUP(A24, maio23!$A$95:$B$117, 2, FALSE),0) -> 0 | G24: =ifna(VLOOKUP(A24, junho23!$A$127:$B$152, 2, FALSE),0) -> 0 | H24: =ifna(VLOOKUP(A24, julho23!$A$139:$B$164, 2, FALSE),0) -> 0 | I24: =ifna(VLOOKUP(A24, Agosto23!$A$127:$B$152, 2, FALSE),0) -> 0 | J24: =ifna(VLOOKUP(A24, setembro23!$A$125:$B$151, 2, FALSE),0) -> 0 | K24: =ifna(VLOOKUP(A24, outubro23!$A$121:$B$146, 2, FALSE),0) -> 0 | L24: =ifna(VLOOKUP(A24, novembro23!$A$121:$B$146, 2, FALSE),0) -> 0 | M24: =ifna(VLOOKUP(A24, Dezembro23!$A$127:$B$152, 2, FALSE),0) -> 0 | N24: =ifna(VLOOKUP(A24, janneiro24!$A$127:$B$152, 2, FALSE),0) -> 0 | O24: =ifna(VLOOKUP(A24, fevereiro24!$A$127:$B$152, 2, FALSE),0) -> 0 | P24: =ifna(VLOOKUP(A24, marco24!$A$127:$B$152, 2, FALSE),0) -> 0 | Q24: =ifna(VLOOKUP(A24, abril24!$A$127:$B$152, 2, FALSE),0) -> 0 | R24: =ifna(VLOOKUP(A24, maio24!$A$127:$B$152, 2, FALSE),0) -> 0 | S24: =ifna(VLOOKUP(A24, 'jun24'!$A$127:$B$152, 2, FALSE),0) -> 0 | T24: =ifna(VLOOKUP(A24, 'set24'!$A$127:$B$152, 2, FALSE),0) -> 0 | U24: =ifna(VLOOKUP(A24, 'jan25'!$A$127:$B$152, 2, FALSE),0) -> 0 | V24: =ifna(VLOOKUP(A24, 'fev25'!$A$132:$B$157, 2, FALSE),0) -> 0 | W24: =ifna(VLOOKUP(A24, 'mar25'!$A$125:$B$153, 2, FALSE),0) -> 0 | X24: =ifna(VLOOKUP(A24, 'abr25'!$A$131:$B$157, 2, FALSE),0) -> 0 | Y24: =ifna(VLOOKUP(A24, 'mai25'!$A$142:$B$174, 2, FALSE),0) -> 0 | Z24: =ifna(VLOOKUP(A24, 'jun25'!$A$141:$B$169, 2, FALSE),0) -> 0 | AA24: =ifna(VLOOKUP(A24, 'jul25'!$A$141:$B$170, 2, FALSE),0) -> 0 | AB24: =ifna(VLOOKUP(A24, 'ago25'!$A$141:$B$170, 2, FALSE),0) -> 0 | AC24: =AVERAGE(X24:AA24) -> 0
A25: Iptu | B25: =0 -> 0 | C25: =0 -> 0 | D25: =ifna(VLOOKUP(A25, marco23!$A$97:$B$119, 2, FALSE),0) -> 64.9 | E25: =ifna(VLOOKUP(A25, abril23!$A$82:$B$103, 2, FALSE),0) -> 0 | F25: =ifna(VLOOKUP(A25, maio23!$A$95:$B$117, 2, FALSE),0) -> 0 | G25: =ifna(VLOOKUP(A25, junho23!$A$127:$B$152, 2, FALSE),0) -> 0 | H25: =ifna(VLOOKUP(A25, julho23!$A$139:$B$164, 2, FALSE),0) -> 0 | I25: =ifna(VLOOKUP(A25, Agosto23!$A$127:$B$152, 2, FALSE),0) -> 0 | J25: =ifna(VLOOKUP(A25, setembro23!$A$125:$B$151, 2, FALSE),0) -> 0 | K25: =ifna(VLOOKUP(A25, outubro23!$A$121:$B$146, 2, FALSE),0) -> 0 | L25: =ifna(VLOOKUP(A25, novembro23!$A$121:$B$146, 2, FALSE),0) -> 0 | M25: =ifna(VLOOKUP(A25, Dezembro23!$A$127:$B$152, 2, FALSE),0) -> 0 | N25: =ifna(VLOOKUP(A25, janneiro24!$A$127:$B$152, 2, FALSE),0) -> 0 | O25: =ifna(VLOOKUP(A25, fevereiro24!$A$127:$B$152, 2, FALSE),0) -> 0 | P25: =ifna(VLOOKUP(A25, marco24!$A$127:$B$152, 2, FALSE),0) -> 0 | Q25: =ifna(VLOOKUP(A25, abril24!$A$127:$B$152, 2, FALSE),0) -> 0 | R25: =ifna(VLOOKUP(A25, maio24!$A$127:$B$152, 2, FALSE),0) -> 0 | S25: =ifna(VLOOKUP(A25, 'jun24'!$A$127:$B$152, 2, FALSE),0) -> 0 | T25: =ifna(VLOOKUP(A25, 'set24'!$A$127:$B$152, 2, FALSE),0) -> 0 | U25: =ifna(VLOOKUP(A25, 'jan25'!$A$127:$B$152, 2, FALSE),0) -> 0 | V25: =ifna(VLOOKUP(A25, 'fev25'!$A$132:$B$157, 2, FALSE),0) -> 0 | W25: =ifna(VLOOKUP(A25, 'mar25'!$A$125:$B$153, 2, FALSE),0) -> 0 | X25: =ifna(VLOOKUP(A25, 'abr25'!$A$131:$B$157, 2, FALSE),0) -> 0 | Y25: =ifna(VLOOKUP(A25, 'mai25'!$A$142:$B$174, 2, FALSE),0) -> 0 | Z25: =ifna(VLOOKUP(A25, 'jun25'!$A$141:$B$169, 2, FALSE),0) -> 0 | AA25: =ifna(VLOOKUP(A25, 'jul25'!$A$141:$B$170, 2, FALSE),0) -> 0 | AB25: =ifna(VLOOKUP(A25, 'ago25'!$A$141:$B$170, 2, FALSE),0) -> 0 | AC25: =AVERAGE(X25:AA25) -> 0
A26: manutencao veiculo | B26: =0 -> 0 | C26: =0 -> 0 | D26: =ifna(VLOOKUP(A26, marco23!$A$97:$B$119, 2, FALSE),0) -> 693 | E26: =ifna(VLOOKUP(A26, abril23!$A$82:$B$103, 2, FALSE),0) -> 0 | F26: =ifna(VLOOKUP(A26, maio23!$A$95:$B$117, 2, FALSE),0) -> 0 | G26: =ifna(VLOOKUP(A26, junho23!$A$127:$B$152, 2, FALSE),0) -> 0 | H26: =ifna(VLOOKUP(A26, julho23!$A$139:$B$164, 2, FALSE),0) -> 72 | I26: =ifna(VLOOKUP(A26, Agosto23!$A$127:$B$152, 2, FALSE),0) -> 0 | J26: =ifna(VLOOKUP(A26, setembro23!$A$125:$B$151, 2, FALSE),0) -> 0 | K26: =ifna(VLOOKUP(A26, outubro23!$A$121:$B$146, 2, FALSE),0) -> 0 | L26: =ifna(VLOOKUP(A26, novembro23!$A$121:$B$146, 2, FALSE),0) -> 0 | M26: =ifna(VLOOKUP(A26, Dezembro23!$A$127:$B$152, 2, FALSE),0) -> 32 | N26: =ifna(VLOOKUP(A26, janneiro24!$A$127:$B$152, 2, FALSE),0) -> 0 | O26: =ifna(VLOOKUP(A26, fevereiro24!$A$127:$B$152, 2, FALSE),0) -> 0 | P26: =ifna(VLOOKUP(A26, marco24!$A$127:$B$152, 2, FALSE),0) -> 0 | Q26: =ifna(VLOOKUP(A26, abril24!$A$127:$B$152, 2, FALSE),0) -> 0 | R26: =ifna(VLOOKUP(A26, maio24!$A$127:$B$152, 2, FALSE),0) -> 0 | S26: =ifna(VLOOKUP(A26, 'jun24'!$A$127:$B$152, 2, FALSE),0) -> 0 | T26: =ifna(VLOOKUP(A26, 'set24'!$A$127:$B$152, 2, FALSE),0) -> 0 | U26: =ifna(VLOOKUP(A26, 'jan25'!$A$127:$B$152, 2, FALSE),0) -> 0 | V26: =ifna(VLOOKUP(A26, 'fev25'!$A$132:$B$157, 2, FALSE),0) -> 0 | W26: =ifna(VLOOKUP(A26, 'mar25'!$A$125:$B$153, 2, FALSE),0) -> 0 | X26: =ifna(VLOOKUP(A26, 'abr25'!$A$131:$B$157, 2, FALSE),0) -> 0 | Y26: =ifna(VLOOKUP(A26, 'mai25'!$A$142:$B$174, 2, FALSE),0) -> 80.38 | Z26: =ifna(VLOOKUP(A26, 'jun25'!$A$141:$B$169, 2, FALSE),0) -> 0 | AA26: =ifna(VLOOKUP(A26, 'jul25'!$A$141:$B$170, 2, FALSE),0) -> 0 | AB26: =ifna(VLOOKUP(A26, 'ago25'!$A$141:$B$170, 2, FALSE),0) -> 0 | AC26: =AVERAGE(X26:AA26) -> 20.095
A27: Padaria | B27: =0 -> 0 | C27: =0 -> 0 | D27: =ifna(VLOOKUP(A27, marco23!$A$97:$B$119, 2, FALSE),0) -> 0 | E27: =ifna(VLOOKUP(A27, abril23!$A$82:$B$103, 2, FALSE),0) -> 12 | F27: =ifna(VLOOKUP(A27, maio23!$A$95:$B$117, 2, FALSE),0) -> 0 | G27: =ifna(VLOOKUP(A27, junho23!$A$127:$B$152, 2, FALSE),0) -> 36 | H27: =ifna(VLOOKUP(A27, julho23!$A$139:$B$164, 2, FALSE),0) -> 8 | I27: =ifna(VLOOKUP(A27, Agosto23!$A$127:$B$152, 2, FALSE),0) -> 29 | J27: =ifna(VLOOKUP(A27, setembro23!$A$125:$B$151, 2, FALSE),0) -> 38.4 | K27: =ifna(VLOOKUP(A27, outubro23!$A$121:$B$146, 2, FALSE),0) -> 34 | L27: =ifna(VLOOKUP(A27, novembro23!$A$121:$B$146, 2, FALSE),0) -> 38 | M27: =ifna(VLOOKUP(A27, Dezembro23!$A$127:$B$152, 2, FALSE),0) -> 46.4 | N27: =ifna(VLOOKUP(A27, janneiro24!$A$127:$B$152, 2, FALSE),0) -> 24.6 | O27: =ifna(VLOOKUP(A27, fevereiro24!$A$127:$B$152, 2, FALSE),0) -> 24.6 | P27: =ifna(VLOOKUP(A27, marco24!$A$127:$B$152, 2, FALSE),0) -> 51.5 | Q27: =ifna(VLOOKUP(A27, abril24!$A$127:$B$152, 2, FALSE),0) -> 24 | R27: =ifna(VLOOKUP(A27, maio24!$A$127:$B$152, 2, FALSE),0) -> 42 | S27: =ifna(VLOOKUP(A27, 'jun24'!$A$127:$B$152, 2, FALSE),0) -> 69.99 | T27: =ifna(VLOOKUP(A27, 'set24'!$A$127:$B$152, 2, FALSE),0) -> 27 | U27: =ifna(VLOOKUP(A27, 'jan25'!$A$127:$B$152, 2, FALSE),0) -> 0 | V27: =ifna(VLOOKUP(A27, 'fev25'!$A$132:$B$157, 2, FALSE),0) -> 38 | W27: =ifna(VLOOKUP(A27, 'mar25'!$A$125:$B$153, 2, FALSE),0) -> 48 | X27: =ifna(VLOOKUP(A27, 'abr25'!$A$131:$B$157, 2, FALSE),0) -> 56.13 | Y27: =ifna(VLOOKUP(A27, 'mai25'!$A$142:$B$174, 2, FALSE),0) -> 82.8 | Z27: =ifna(VLOOKUP(A27, 'jun25'!$A$141:$B$169, 2, FALSE),0) -> 60.7 | AA27: =ifna(VLOOKUP(A27, 'jul25'!$A$141:$B$170, 2, FALSE),0) -> 64 | AB27: =ifna(VLOOKUP(A27, 'ago25'!$A$141:$B$170, 2, FALSE),0) -> 439.35 | AC27: =AVERAGE(X27:AA27) -> 65.9075
A28: Manutenção casa | D28: =ifna(VLOOKUP(A28, marco23!$A$97:$B$119, 2, FALSE),0) -> 0 | E28: =ifna(VLOOKUP(A28, abril23!$A$82:$B$103, 2, FALSE),0) -> 0 | F28: =ifna(VLOOKUP(A28, maio23!$A$95:$B$117, 2, FALSE),0) -> 0 | G28: =ifna(VLOOKUP(A28, junho23!$A$127:$B$152, 2, FALSE),0) -> 145 | H28: =ifna(VLOOKUP(A28, julho23!$A$139:$B$164, 2, FALSE),0) -> 644.16 | I28: =ifna(VLOOKUP(A28, Agosto23!$A$127:$B$152, 2, FALSE),0) -> 0 | J28: =ifna(VLOOKUP(A28, setembro23!$A$125:$B$151, 2, FALSE),0) -> 0 | K28: =ifna(VLOOKUP(A28, outubro23!$A$121:$B$146, 2, FALSE),0) -> 0 | L28: =ifna(VLOOKUP(A28, novembro23!$A$121:$B$146, 2, FALSE),0) -> 0 | M28: =ifna(VLOOKUP(A28, Dezembro23!$A$127:$B$152, 2, FALSE),0) -> 0 | N28: =ifna(VLOOKUP(A28, janneiro24!$A$127:$B$152, 2, FALSE),0) -> 136.2 | O28: =ifna(VLOOKUP(A28, fevereiro24!$A$127:$B$152, 2, FALSE),0) -> 136.2 | P28: =ifna(VLOOKUP(A28, marco24!$A$127:$B$152, 2, FALSE),0) -> 0 | Q28: =ifna(VLOOKUP(A28, abril24!$A$127:$B$152, 2, FALSE),0) -> 0 | R28: =ifna(VLOOKUP(A28, maio24!$A$127:$B$152, 2, FALSE),0) -> 0 | S28: =ifna(VLOOKUP(A28, 'jun24'!$A$127:$B$152, 2, FALSE),0) -> 0 | T28: =ifna(VLOOKUP(A28, 'set24'!$A$127:$B$152, 2, FALSE),0) -> 0 | U28: =ifna(VLOOKUP(A28, 'jan25'!$A$127:$B$152, 2, FALSE),0) -> 0 | V28: =ifna(VLOOKUP(A28, 'fev25'!$A$132:$B$157, 2, FALSE),0) -> 0 | W28: =ifna(VLOOKUP(A28, 'mar25'!$A$125:$B$153, 2, FALSE),0) -> 81.4 | X28: =ifna(VLOOKUP(A28, 'abr25'!$A$131:$B$157, 2, FALSE),0) -> 109 | Y28: =ifna(VLOOKUP(A28, 'mai25'!$A$142:$B$174, 2, FALSE),0) -> 26.1 | Z28: =ifna(VLOOKUP(A28, 'jun25'!$A$141:$B$169, 2, FALSE),0) -> 0 | AA28: =ifna(VLOOKUP(A28, 'jul25'!$A$141:$B$170, 2, FALSE),0) -> 19.99 | AB28: =ifna(VLOOKUP(A28, 'ago25'!$A$141:$B$170, 2, FALSE),0) -> 77.8 | AC28: =AVERAGE(X28:AA28) -> 38.7725
A29: manutenção domiciliar | D29: =ifna(VLOOKUP(A29, marco23!$A$97:$B$119, 2, FALSE),0) -> 0 | E29: =ifna(VLOOKUP(A29, abril23!$A$82:$B$103, 2, FALSE),0) -> 0 | F29: =ifna(VLOOKUP(A29, maio23!$A$95:$B$117, 2, FALSE),0) -> 0 | G29: =ifna(VLOOKUP(A29, junho23!$A$127:$B$152, 2, FALSE),0) -> 62.9 | H29: =ifna(VLOOKUP(A29, julho23!$A$139:$B$164, 2, FALSE),0) -> 4 | I29: =ifna(VLOOKUP(A29, Agosto23!$A$127:$B$152, 2, FALSE),0) -> 45.5 | J29: =ifna(VLOOKUP(A29, setembro23!$A$125:$B$151, 2, FALSE),0) -> 50 | K29: =ifna(VLOOKUP(A29, outubro23!$A$121:$B$146, 2, FALSE),0) -> 70.84 | L29: =ifna(VLOOKUP(A29, novembro23!$A$121:$B$146, 2, FALSE),0) -> 418.57 | M29: =ifna(VLOOKUP(A29, Dezembro23!$A$127:$B$152, 2, FALSE),0) -> 28 | N29: =ifna(VLOOKUP(A29, janneiro24!$A$127:$B$152, 2, FALSE),0) -> 0 | O29: =ifna(VLOOKUP(A29, fevereiro24!$A$127:$B$152, 2, FALSE),0) -> 0 | P29: =ifna(VLOOKUP(A29, marco24!$A$127:$B$152, 2, FALSE),0) -> 279.9 | Q29: =ifna(VLOOKUP(A29, abril24!$A$127:$B$152, 2, FALSE),0) -> 455.46 | R29: =ifna(VLOOKUP(A29, maio24!$A$127:$B$152, 2, FALSE),0) -> 326.14 | S29: =ifna(VLOOKUP(A29, 'jun24'!$A$127:$B$152, 2, FALSE),0) -> 88.48 | T29: =ifna(VLOOKUP(A29, 'set24'!$A$127:$B$152, 2, FALSE),0) -> 0 | U29: =ifna(VLOOKUP(A29, 'jan25'!$A$127:$B$152, 2, FALSE),0) -> 0 | V29: =ifna(VLOOKUP(A29, 'fev25'!$A$132:$B$157, 2, FALSE),0) -> 1052.36 | W29: =ifna(VLOOKUP(A29, 'mar25'!$A$125:$B$153, 2, FALSE),0) -> 20 | X29: =ifna(VLOOKUP(A29, 'abr25'!$A$131:$B$157, 2, FALSE),0) -> 20 | Y29: =ifna(VLOOKUP(A29, 'mai25'!$A$142:$B$174, 2, FALSE),0) -> 550.99 | Z29: =ifna(VLOOKUP(A29, 'jun25'!$A$141:$B$169, 2, FALSE),0) -> 20 | AA29: =ifna(VLOOKUP(A29, 'jul25'!$A$141:$B$170, 2, FALSE),0) -> 93.59 | AB29: =ifna(VLOOKUP(A29, 'ago25'!$A$141:$B$170, 2, FALSE),0) -> 20 | AC29: =AVERAGE(X29:AA29) -> 171.145
A30: manutencao veicular | D30: =ifna(VLOOKUP(A30, marco23!$A$97:$B$119, 2, FALSE),0) -> 0 | E30: =ifna(VLOOKUP(A30, abril23!$A$82:$B$103, 2, FALSE),0) -> 650 | F30: =ifna(VLOOKUP(A30, maio23!$A$95:$B$117, 2, FALSE),0) -> 2097 | G30: =ifna(VLOOKUP(A30, junho23!$A$127:$B$152, 2, FALSE),0) -> 136.68 | H30: =ifna(VLOOKUP(A30, julho23!$A$139:$B$164, 2, FALSE),0) -> 312 | I30: =ifna(VLOOKUP(A30, Agosto23!$A$127:$B$152, 2, FALSE),0) -> 168.66 | J30: =ifna(VLOOKUP(A30, setembro23!$A$125:$B$151, 2, FALSE),0) -> 999.28 | K30: =ifna(VLOOKUP(A30, outubro23!$A$121:$B$146, 2, FALSE),0) -> 610 | L30: =ifna(VLOOKUP(A30, novembro23!$A$121:$B$146, 2, FALSE),0) -> 51 | M30: =ifna(VLOOKUP(A30, Dezembro23!$A$127:$B$152, 2, FALSE),0) -> 1087 | N30: =ifna(VLOOKUP(A30, janneiro24!$A$127:$B$152, 2, FALSE),0) -> 0 | O30: =ifna(VLOOKUP(A30, fevereiro24!$A$127:$B$152, 2, FALSE),0) -> 0 | P30: =ifna(VLOOKUP(A30, marco24!$A$127:$B$152, 2, FALSE),0) -> 1357 | Q30: =ifna(VLOOKUP(A30, abril24!$A$127:$B$152, 2, FALSE),0) -> 0 | R30: =ifna(VLOOKUP(A30, maio24!$A$127:$B$152, 2, FALSE),0) -> 0 | S30: =ifna(VLOOKUP(A30, 'jun24'!$A$127:$B$152, 2, FALSE),0) -> 0 | T30: =ifna(VLOOKUP(A30, 'set24'!$A$127:$B$152, 2, FALSE),0) -> 411 | U30: =ifna(VLOOKUP(A30, 'jan25'!$A$127:$B$152, 2, FALSE),0) -> 0 | V30: =ifna(VLOOKUP(A30, 'fev25'!$A$132:$B$157, 2, FALSE),0) -> 0 | W30: =ifna(VLOOKUP(A30, 'mar25'!$A$125:$B$153, 2, FALSE),0) -> 208.46 | X30: =ifna(VLOOKUP(A30, 'abr25'!$A$131:$B$157, 2, FALSE),0) -> 489.75 | Y30: =ifna(VLOOKUP(A30, 'mai25'!$A$142:$B$174, 2, FALSE),0) -> 0 | Z30: =ifna(VLOOKUP(A30, 'jun25'!$A$141:$B$169, 2, FALSE),0) -> 45 | AA30: =ifna(VLOOKUP(A30, 'jul25'!$A$141:$B$170, 2, FALSE),0) -> 0 | AB30: =ifna(VLOOKUP(A30, 'ago25'!$A$141:$B$170, 2, FALSE),0) -> 68 | AC30: =AVERAGE(X30:AA30) -> 133.6875
A31: ferias | D31: =ifna(VLOOKUP(A31, marco23!$A$97:$B$119, 2, FALSE),0) -> 0 | E31: =ifna(VLOOKUP(A31, abril23!$A$82:$B$103, 2, FALSE),0) -> 0 | F31: =ifna(VLOOKUP(A31, maio23!$A$95:$B$117, 2, FALSE),0) -> 0 | G31: =ifna(VLOOKUP(A31, junho23!$A$127:$B$152, 2, FALSE),0) -> 0 | H31: =ifna(VLOOKUP(A31, julho23!$A$139:$B$164, 2, FALSE),0) -> 3816.74 | I31: =ifna(VLOOKUP(A31, Agosto23!$A$127:$B$152, 2, FALSE),0) -> 0 | J31: =ifna(VLOOKUP(A31, setembro23!$A$125:$B$151, 2, FALSE),0) -> 160 | K31: =ifna(VLOOKUP(A31, outubro23!$A$121:$B$146, 2, FALSE),0) -> 0 | L31: =ifna(VLOOKUP(A31, novembro23!$A$121:$B$146, 2, FALSE),0) -> 0 | M31: =ifna(VLOOKUP(A31, Dezembro23!$A$127:$B$152, 2, FALSE),0) -> 0 | N31: =ifna(VLOOKUP(A31, janneiro24!$A$127:$B$152, 2, FALSE),0) -> 0 | O31: =ifna(VLOOKUP(A31, fevereiro24!$A$127:$B$152, 2, FALSE),0) -> 0 | P31: =ifna(VLOOKUP(A31, marco24!$A$127:$B$152, 2, FALSE),0) -> 0 | Q31: =ifna(VLOOKUP(A31, abril24!$A$127:$B$152, 2, FALSE),0) -> 0 | R31: =ifna(VLOOKUP(A31, maio24!$A$127:$B$152, 2, FALSE),0) -> 0 | S31: =ifna(VLOOKUP(A31, 'jun24'!$A$127:$B$152, 2, FALSE),0) -> 0 | T31: =ifna(VLOOKUP(A31, 'set24'!$A$127:$B$152, 2, FALSE),0) -> 0 | U31: =ifna(VLOOKUP(A31, 'jan25'!$A$127:$B$152, 2, FALSE),0) -> 0 | V31: =ifna(VLOOKUP(A31, 'fev25'!$A$132:$B$157, 2, FALSE),0) -> 0 | W31: =ifna(VLOOKUP(A31, 'mar25'!$A$125:$B$153, 2, FALSE),0) -> 0 | X31: =ifna(VLOOKUP(A31, 'abr25'!$A$131:$B$157, 2, FALSE),0) -> 0 | Y31: =ifna(VLOOKUP(A31, 'mai25'!$A$142:$B$174, 2, FALSE),0) -> 0 | Z31: =ifna(VLOOKUP(A31, 'jun25'!$A$141:$B$169, 2, FALSE),0) -> 0 | AA31: =ifna(VLOOKUP(A31, 'jul25'!$A$141:$B$170, 2, FALSE),0) -> 0 | AB31: =ifna(VLOOKUP(A31, 'ago25'!$A$141:$B$170, 2, FALSE),0) -> 0 | AC31: =AVERAGE(X31:AA31) -> 0
A32: projetos | D32: =ifna(VLOOKUP(A32, marco23!$A$97:$B$119, 2, FALSE),0) -> 0 | E32: =ifna(VLOOKUP(B32, marco23!$A$97:$B$119, 2, FALSE),0) -> 0 | F32: =ifna(VLOOKUP(C32, marco23!$A$97:$B$119, 2, FALSE),0) -> 0 | G32: =ifna(VLOOKUP(D32, marco23!$A$97:$B$119, 2, FALSE),0) -> 0 | H32: =ifna(VLOOKUP(E32, marco23!$A$97:$B$119, 2, FALSE),0) -> 0 | I32: =ifna(VLOOKUP(F32, marco23!$A$97:$B$119, 2, FALSE),0) -> 0 | J32: =ifna(VLOOKUP(G32, marco23!$A$97:$B$119, 2, FALSE),0) -> 0 | K32: =ifna(VLOOKUP(H32, marco23!$A$97:$B$119, 2, FALSE),0) -> 0 | ... P32: =ifna(VLOOKUP(M32, marco23!$A$97:$B$119, 2, FALSE),0) -> 0 | Q32: =ifna(VLOOKUP(A32, abril24!$A$127:$B$152, 2, FALSE),0) -> 0 | R32: =ifna(VLOOKUP(A32, maio24!$A$127:$B$152, 2, FALSE),0) -> 591.51 | S32: =ifna(VLOOKUP(A32, 'jun24'!$A$127:$B$152, 2, FALSE),0) -> 0 | T32: =ifna(VLOOKUP(A32, 'set24'!$A$127:$B$152, 2, FALSE),0) -> 0 | U32: =ifna(VLOOKUP(A32, 'jan25'!$A$127:$B$152, 2, FALSE),0) -> 0 | V32: =ifna(VLOOKUP(A32, 'fev25'!$A$132:$B$157, 2, FALSE),0) -> 111.28 | W32: =ifna(VLOOKUP(A32, 'mar25'!$A$125:$B$153, 2, FALSE),0) -> 0 | X32: =ifna(VLOOKUP(A32, 'abr25'!$A$131:$B$157, 2, FALSE),0) -> 0 | Y32: =ifna(VLOOKUP(A32, 'mai25'!$A$142:$B$174, 2, FALSE),0) -> 1596.5 | Z32: =ifna(VLOOKUP(A32, 'jun25'!$A$141:$B$169, 2, FALSE),0) -> 13.8 | AA32: =ifna(VLOOKUP(A32, 'jul25'!$A$141:$B$170, 2, FALSE),0) -> 297.52 | AB32: =ifna(VLOOKUP(A32, 'ago25'!$A$141:$B$170, 2, FALSE),0) -> 248.79 | AC32: =AVERAGE(X32:AA32) -> 476.955
A33: pix aline | U33: =ifna(VLOOKUP(A33, 'jan25'!$A$127:$B$152, 2, FALSE),0) -> 0 | V33: =ifna(VLOOKUP(A33, 'fev25'!$A$132:$B$157, 2, FALSE),0) -> 100 | W33: =ifna(VLOOKUP(A33, 'mar25'!$A$125:$B$153, 2, FALSE),0) -> 630 | X33: =ifna(VLOOKUP(A33, 'abr25'!$A$131:$B$157, 2, FALSE),0) -> 600 | Y33: =ifna(VLOOKUP(A33, 'mai25'!$A$142:$B$174, 2, FALSE),0) -> 150 | Z33: =ifna(VLOOKUP(A33, 'jun25'!$A$141:$B$169, 2, FALSE),0) -> 778 | AA33: =ifna(VLOOKUP(A33, 'jul25'!$A$141:$B$170, 2, FALSE),0) -> 500 | AB33: =ifna(VLOOKUP(A33, 'ago25'!$A$141:$B$170, 2, FALSE),0) -> 1337.62 | AC33: =AVERAGE(X33:AA33) -> 507
A34: painel solar | U34: =ifna(VLOOKUP(A34, 'jan25'!$A$127:$B$152, 2, FALSE),0) -> 0 | V34: =ifna(VLOOKUP(A34, 'fev25'!$A$132:$B$157, 2, FALSE),0) -> 0 | W34: =ifna(VLOOKUP(A34, 'mar25'!$A$125:$B$153, 2, FALSE),0) -> 2177.64 | X34: =ifna(VLOOKUP(A34, 'abr25'!$A$131:$B$157, 2, FALSE),0) -> 6446.76 | Y34: =ifna(VLOOKUP(A34, 'mai25'!$A$142:$B$174, 2, FALSE),0) -> 777.56 | Z34: =ifna(VLOOKUP(A34, 'jun25'!$A$141:$B$169, 2, FALSE),0) -> 777.56 | AA34: =ifna(VLOOKUP(A34, 'jul25'!$A$141:$B$170, 2, FALSE),0) -> 777.56 | AB34: =ifna(VLOOKUP(A34, 'ago25'!$A$141:$B$170, 2, FALSE),0) -> 777.56 | AC34: =AVERAGE(X34:AA34) -> 2194.86
A35: dentista | U35: =ifna(VLOOKUP(A35, 'jan25'!$A$127:$B$152, 2, FALSE),0) -> 0 | V35: =ifna(VLOOKUP(A35, 'fev25'!$A$132:$B$157, 2, FALSE),0) -> 140 | W35: =ifna(VLOOKUP(A35, 'mar25'!$A$125:$B$153, 2, FALSE),0) -> 140 | X35: =ifna(VLOOKUP(A35, 'abr25'!$A$131:$B$157, 2, FALSE),0) -> 140 | Y35: =ifna(VLOOKUP(A35, 'mai25'!$A$142:$B$174, 2, FALSE),0) -> 140 | Z35: =ifna(VLOOKUP(A35, 'jun25'!$A$141:$B$169, 2, FALSE),0) -> 140 | AA35: =ifna(VLOOKUP(A35, 'jul25'!$A$141:$B$170, 2, FALSE),0) -> 140 | AB35: =ifna(VLOOKUP(A35, 'ago25'!$A$141:$B$170, 2, FALSE),0) -> 0 | AC35: =AVERAGE(X35:AA35) -> 140
A36: reforma casa | U36: =ifna(VLOOKUP(A36, 'jan25'!$A$127:$B$152, 2, FALSE),0) -> 0 | V36: =ifna(VLOOKUP(A36, 'fev25'!$A$132:$B$157, 2, FALSE),0) -> 328.57 | W36: =ifna(VLOOKUP(A36, 'mar25'!$A$125:$B$153, 2, FALSE),0) -> 328.55 | X36: =ifna(VLOOKUP(A36, 'abr25'!$A$131:$B$157, 2, FALSE),0) -> 0 | Y36: =ifna(VLOOKUP(A36, 'mai25'!$A$142:$B$174, 2, FALSE),0) -> 328.55 | Z36: =ifna(VLOOKUP(A36, 'jun25'!$A$141:$B$169, 2, FALSE),0) -> 328.55 | AA36: =ifna(VLOOKUP(A36, 'jul25'!$A$141:$B$170, 2, FALSE),0) -> 328.55 | AB36: =ifna(VLOOKUP(A36, 'ago25'!$A$141:$B$170, 2, FALSE),0) -> 328.55 | AC36: =AVERAGE(X36:AA36) -> 246.4125
